Workbook

Sheet Input
A1: FUEL ROCK (PTY) LTD
A2: SITE NAME: | B2: ENGEN JETPARK
A4: Daily Management - Input
A6: Month Under Review: | B6: 46143
B8: Day | C8: Date
B10: Friday | C10: 46143 | E10: Copy Day & Date till last day of the month
B11: Saturday | C11: 46144
B12: Sunday | C12: 46145
B13: Monday | C13: 46146
B14: Tuesday | C14: 46147
B15: Wednesday | C15: 46148
B16: Thursday | C16: 46149
B17: Friday | C17: 46150
B18: Saturday | C18: 46151
B19: Sunday | C19: 46152
B20: Monday | C20: 46153
B21: Tuesday | C21: 46154
B22: Wednesday | C22: 46155
... B40: Sunday | C40: 46173
B43: 1 | C43: 2 | D43: 3 | E43: 4 | F43: 5 | G43: 6
A44: Cashiers | B44: Mandla | C44: Caroline | D44: Siyabonga | E44: Thumelo | F44: Cashier 5 | G44: Cashier 6
B47: 1 | C47: 2 | D47: 3 | E47: 4 | F47: 5
A48: Fuel Litres - Opening
A49: - Diesel
A50: - ULP 93
A51: - ULP 95
A54: Creditors
A55: - Aksia Sales
A56: - Albany
A57: - Atlantic Ice
A58: - Bake It Easy
A59: - Bamco Tabacco
A60: - Blue Ribbon
A61: - Catercorp
... A97: - Other 10

Sheet Summary
A1: =+Input!B2 -> ENGEN JETPARK
A3: Monthly Summary | B3: =+Input!B6 -> 46143
A5: DATA: LITRES | B5: Diesel | C5: ULP: 93 | D5: ULP: 95
A6: - Litres Purchased | B6: =+'SS26'!B8 -> 0 | C6: =+'SS26'!C8 -> 0 | D6: =+'SS26'!D8 -> 0
A7: - Litres Sold | B7: =+'SS26'!B9 -> 1659.39 | C7: =+'SS26'!C9 -> 40.06 | D7: =+'SS26'!D9 -> 1920.7
A8: - Closing Dip: ATG | B8: =+'SS26'!B11 -> 0 | C8: =+'SS26'!C11 -> 0 | D8: =+'SS26'!D11 -> 0
A9: - Selling Price | B9: =+'30'!B14 -> 0 | C9: =+'30'!C14 -> 0 | D9: =+'30'!D14 -> 0
A10: - Cost Price | B10: =+'30'!B15 -> 0 | C10: =+'30'!C15 -> 0 | D10: =+'30'!D15 -> 0
A11: - Gross Profit | B11: =+B9-B10 -> 0 | C11: =+C9-C10 -> 0 | D11: =+D9-D10 -> 0
A12: - Gross Profit % | B12: =+B11/B9 -> #DIV/0! | C12: =+C11/C9 -> #DIV/0! | D12: =+D11/D9 -> #DIV/0!
A15: DAY END REPORT | B15: TOTAL | C15: 1 | D15: =+C15+1 -> 2 | E15: =+D15+1 -> 3 | F15: =+E15+1 -> 4 | G15: =+F15+1 -> 5 | H15: =+G15+1 -> 6 | I15: =+H15+1 -> 7 | J15: =+I15+1 -> 8 | K15: =+J15+1 -> 9 | ... AG15: =+AF15+1 -> 31
A16: - Total Sales | B16: =SUM(C16:AG16) -> 0 | C16: =+'1'!B21 -> 0 | D16: =+'2'!B21 -> 0 | E16: =+'3'!B21 -> 0 | F16: =+'4'!B21 -> 0 | G16: =+'5'!B21 -> 0 | H16: =+'6'!B21 -> 0 | I16: =+'7'!B21 -> 0 | J16: =+'8'!B21 -> 0 | K16: =+'9'!B21 -> 0 | L16: =+'10'!B21 -> 0 | M16: =+'11'!B21 -> 0 | N16: =+'12'!B21 -> 0 | O16: =+'13'!B21 -> 0 | P16: =+'14'!B21 -> 0 | Q16: =+'15'!B21 -> 0 | R16: =+'16'!B21 -> 0 | S16: =+'17'!B21 -> 0 | T16: =+'18'!B21 -> 0 | U16: =+'19'!B21 -> 0 | V16: =+'20'!B21 -> 0 | W16: =+'21'!B21 -> 0 | X16: =+'22'!B21 -> 0 | Y16: =+'23'!B21 -> 0 | Z16: =+'24'!B21 -> 0 | AA16: =+'25'!B21 -> 0 | AB16: =+'26'!B21 -> 0 | AC16: =+'27'!B21 -> 0 | AD16: =+'28'!B21 -> 0 | AE16: =+'29'!B21 -> 0 | AF16: =+'30'!B21 -> 0 | AG16: =+'31'!B21 -> 0
A17: - Less: Returns (Show as a negative) | B17: =SUM(C17:AG17) -> 0 | C17: =+'1'!B22 -> 0 | D17: =+'2'!B22 -> 0 | E17: =+'3'!B22 -> 0 | F17: =+'4'!B22 -> 0 | G17: =+'5'!B22 -> 0 | H17: =+'6'!B22 -> 0 | I17: =+'7'!B22 -> 0 | J17: =+'8'!B22 -> 0 | K17: =+'9'!B22 -> 0 | L17: =+'10'!B22 -> 0 | M17: =+'11'!B22 -> 0 | N17: =+'12'!B22 -> 0 | O17: =+'13'!B22 -> 0 | P17: =+'14'!B22 -> 0 | Q17: =+'15'!B22 -> 0 | R17: =+'16'!B22 -> 0 | S17: =+'17'!B22 -> 0 | T17: =+'18'!B22 -> 0 | U17: =+'19'!B22 -> 0 | V17: =+'20'!B22 -> 0 | W17: =+'21'!B22 -> 0 | X17: =+'22'!B22 -> 0 | Y17: =+'23'!B22 -> 0 | Z17: =+'24'!B22 -> 0 | AA17: =+'25'!B22 -> 0 | AB17: =+'26'!B22 -> 0 | AC17: =+'27'!B22 -> 0 | AD17: =+'28'!B22 -> 0 | AE17: =+'29'!B22 -> 0 | AF17: =+'30'!B22 -> 0 | AG17: =+'31'!B22 -> 0
A18: - Total Net Sales | B18: =SUM(B16:B17) -> 0 | C18: =SUM(C16:C17) -> 0 | D18: =SUM(D16:D17) -> 0 | E18: =SUM(E16:E17) -> 0 | F18: =SUM(F16:F17) -> 0 | G18: =SUM(G16:G17) -> 0 | H18: =SUM(H16:H17) -> 0 | I18: =SUM(I16:I17) -> 0 | ... AG18: =SUM(AG16:AG17) -> 0
A21: SALES BY DIVISION | B21: TOTAL | C21: 1 | D21: =+C21+1 -> 2 | E21: =+D21+1 -> 3 | F21: =+E21+1 -> 4 | G21: =+F21+1 -> 5 | H21: =+G21+1 -> 6 | I21: =+H21+1 -> 7 | J21: =+I21+1 -> 8 | K21: =+J21+1 -> 9 | ... AG21: =+AF21+1 -> 31
A22: - Bakery | B22: =SUM(C22:AG22) -> 0 | C22: =+'1'!B27 -> 0 | D22: =+'2'!B27 -> 0 | E22: =+'3'!B27 -> 0 | F22: =+'4'!B27 -> 0 | G22: =+'5'!B27 -> 0 | H22: =+'6'!B27 -> 0 | I22: =+'7'!B27 -> 0 | J22: =+'8'!B27 -> 0 | K22: =+'9'!B27 -> 0 | L22: =+'10'!B27 -> 0 | M22: =+'11'!B27 -> 0 | N22: =+'12'!B27 -> 0 | O22: =+'13'!B27 -> 0 | P22: =+'14'!B27 -> 0 | Q22: =+'15'!B27 -> 0 | R22: =+'16'!B27 -> 0 | S22: =+'17'!B27 -> 0 | T22: =+'18'!B27 -> 0 | U22: =+'19'!B27 -> 0 | V22: =+'20'!B27 -> 0 | W22: =+'21'!B27 -> 0 | X22: =+'22'!B27 -> 0 | Y22: =+'23'!B27 -> 0 | Z22: =+'24'!B27 -> 0 | AA22: =+'25'!B27 -> 0 | AB22: =+'26'!B27 -> 0 | AC22: =+'27'!B27 -> 0 | AD22: =+'28'!B27 -> 0 | AE22: =+'29'!B27 -> 0 | AF22: =+'30'!B27 -> 0 | AG22: =+'31'!B27 -> 0
A23: - Bakpre | B23: =SUM(C23:AG23) -> 0 | C23: =+'1'!B28 -> 0 | D23: =+'2'!B28 -> 0 | E23: =+'3'!B28 -> 0 | F23: =+'4'!B28 -> 0 | G23: =+'5'!B28 -> 0 | H23: =+'6'!B28 -> 0 | I23: =+'7'!B28 -> 0 | J23: =+'8'!B28 -> 0 | K23: =+'9'!B28 -> 0 | L23: =+'10'!B28 -> 0 | M23: =+'11'!B28 -> 0 | N23: =+'12'!B28 -> 0 | O23: =+'13'!B28 -> 0 | P23: =+'14'!B28 -> 0 | Q23: =+'15'!B28 -> 0 | R23: =+'16'!B28 -> 0 | S23: =+'17'!B28 -> 0 | T23: =+'18'!B28 -> 0 | U23: =+'19'!B28 -> 0 | V23: =+'20'!B28 -> 0 | W23: =+'21'!B28 -> 0 | X23: =+'22'!B28 -> 0 | Y23: =+'23'!B28 -> 0 | Z23: =+'24'!B28 -> 0 | AA23: =+'25'!B28 -> 0 | AB23: =+'26'!B28 -> 0 | AC23: =+'27'!B28 -> 0 | AD23: =+'28'!B28 -> 0 | AE23: =+'29'!B28 -> 0 | AF23: =+'30'!B28 -> 0 | AG23: =+'31'!B28 -> 0
A24: - Barist | B24: =SUM(C24:AG24) -> 0 | C24: =+'1'!B29 -> 0 | D24: =+'2'!B29 -> 0 | E24: =+'3'!B29 -> 0 | F24: =+'4'!B29 -> 0 | G24: =+'5'!B29 -> 0 | H24: =+'6'!B29 -> 0 | I24: =+'7'!B29 -> 0 | J24: =+'8'!B29 -> 0 | K24: =+'9'!B29 -> 0 | L24: =+'10'!B29 -> 0 | M24: =+'11'!B29 -> 0 | N24: =+'12'!B29 -> 0 | O24: =+'13'!B29 -> 0 | P24: =+'14'!B29 -> 0 | Q24: =+'15'!B29 -> 0 | R24: =+'16'!B29 -> 0 | S24: =+'17'!B29 -> 0 | T24: =+'18'!B29 -> 0 | U24: =+'19'!B29 -> 0 | V24: =+'20'!B29 -> 0 | W24: =+'21'!B29 -> 0 | X24: =+'22'!B29 -> 0 | Y24: =+'23'!B29 -> 0 | Z24: =+'24'!B29 -> 0 | AA24: =+'25'!B29 -> 0 | AB24: =+'26'!B29 -> 0 | AC24: =+'27'!B29 -> 0 | AD24: =+'28'!B29 -> 0 | AE24: =+'29'!B29 -> 0 | AF24: =+'30'!B29 -> 0 | AG24: =+'31'!B29 -> 0
A25: - Fuel | B25: =SUM(C25:AG25) -> 0 | C25: =+'1'!B30 -> 0 | D25: =+'2'!B30 -> 0 | E25: =+'3'!B30 -> 0 | F25: =+'4'!B30 -> 0 | G25: =+'5'!B30 -> 0 | H25: =+'6'!B30 -> 0 | I25: =+'7'!B30 -> 0 | J25: =+'8'!B30 -> 0 | K25: =+'9'!B30 -> 0 | L25: =+'10'!B30 -> 0 | M25: =+'11'!B30 -> 0 | N25: =+'12'!B30 -> 0 | O25: =+'13'!B30 -> 0 | P25: =+'14'!B30 -> 0 | Q25: =+'15'!B30 -> 0 | R25: =+'16'!B30 -> 0 | S25: =+'17'!B30 -> 0 | T25: =+'18'!B30 -> 0 | U25: =+'19'!B30 -> 0 | V25: =+'20'!B30 -> 0 | W25: =+'21'!B30 -> 0 | X25: =+'22'!B30 -> 0 | Y25: =+'23'!B30 -> 0 | Z25: =+'24'!B30 -> 0 | AA25: =+'25'!B30 -> 0 | AB25: =+'26'!B30 -> 0 | AC25: =+'27'!B30 -> 0 | AD25: =+'28'!B30 -> 0 | AE25: =+'29'!B30 -> 0 | AF25: =+'30'!B30 -> 0 | AG25: =+'31'!B30 -> 0
A26: - Lubes | B26: =SUM(C26:AG26) -> 0 | C26: =+'1'!B31 -> 0 | D26: =+'2'!B31 -> 0 | E26: =+'3'!B31 -> 0 | F26: =+'4'!B31 -> 0 | G26: =+'5'!B31 -> 0 | H26: =+'6'!B31 -> 0 | I26: =+'7'!B31 -> 0 | J26: =+'8'!B31 -> 0 | K26: =+'9'!B31 -> 0 | L26: =+'10'!B31 -> 0 | M26: =+'11'!B31 -> 0 | N26: =+'12'!B31 -> 0 | O26: =+'13'!B31 -> 0 | P26: =+'14'!B31 -> 0 | Q26: =+'15'!B31 -> 0 | R26: =+'16'!B31 -> 0 | S26: =+'17'!B31 -> 0 | T26: =+'18'!B31 -> 0 | U26: =+'19'!B31 -> 0 | V26: =+'20'!B31 -> 0 | W26: =+'21'!B31 -> 0 | X26: =+'22'!B31 -> 0 | Y26: =+'23'!B31 -> 0 | Z26: =+'24'!B31 -> 0 | AA26: =+'25'!B31 -> 0 | AB26: =+'26'!B31 -> 0 | AC26: =+'27'!B31 -> 0 | AD26: =+'28'!B31 -> 0 | AE26: =+'29'!B31 -> 0 | AF26: =+'30'!B31 -> 0 | AG26: =+'31'!B31 -> 0
A27: - VV | B27: =SUM(C27:AG27) -> 0 | C27: =+'1'!B32 -> 0 | D27: =+'2'!B32 -> 0 | E27: =+'3'!B32 -> 0 | F27: =+'4'!B32 -> 0 | G27: =+'5'!B32 -> 0 | H27: =+'6'!B32 -> 0 | I27: =+'7'!B32 -> 0 | J27: =+'8'!B32 -> 0 | K27: =+'9'!B32 -> 0 | L27: =+'10'!B32 -> 0 | M27: =+'11'!B32 -> 0 | N27: =+'12'!B32 -> 0 | O27: =+'13'!B32 -> 0 | P27: =+'14'!B32 -> 0 | Q27: =+'15'!B32 -> 0 | R27: =+'16'!B32 -> 0 | S27: =+'17'!B32 -> 0 | T27: =+'18'!B32 -> 0 | U27: =+'19'!B32 -> 0 | V27: =+'20'!B32 -> 0 | W27: =+'21'!B32 -> 0 | X27: =+'22'!B32 -> 0 | Y27: =+'23'!B32 -> 0 | Z27: =+'24'!B32 -> 0 | AA27: =+'25'!B32 -> 0 | AB27: =+'26'!B32 -> 0 | AC27: =+'27'!B32 -> 0 | AD27: =+'28'!B32 -> 0 | AE27: =+'29'!B32 -> 0 | AF27: =+'30'!B32 -> 0 | AG27: =+'31'!B32 -> 0
A28: - Quickshop | B28: =SUM(C28:AG28) -> 0 | C28: =+'1'!B33 -> 0 | D28: =+'2'!B33 -> 0 | E28: =+'3'!B33 -> 0 | F28: =+'4'!B33 -> 0 | G28: =+'5'!B33 -> 0 | H28: =+'6'!B33 -> 0 | I28: =+'7'!B33 -> 0 | J28: =+'8'!B33 -> 0 | K28: =+'9'!B33 -> 0 | L28: =+'10'!B33 -> 0 | M28: =+'11'!B33 -> 0 | N28: =+'12'!B33 -> 0 | O28: =+'13'!B33 -> 0 | P28: =+'14'!B33 -> 0 | Q28: =+'15'!B33 -> 0 | R28: =+'16'!B33 -> 0 | S28: =+'17'!B33 -> 0 | T28: =+'18'!B33 -> 0 | U28: =+'19'!B33 -> 0 | V28: =+'20'!B33 -> 0 | W28: =+'21'!B33 -> 0 | X28: =+'22'!B33 -> 0 | Y28: =+'23'!B33 -> 0 | Z28: =+'24'!B33 -> 0 | AA28: =+'25'!B33 -> 0 | AB28: =+'26'!B33 -> 0 | AC28: =+'27'!B33 -> 0 | AD28: =+'28'!B33 -> 0 | AE28: =+'29'!B33 -> 0 | AF28: =+'30'!B33 -> 0 | AG28: =+'31'!B33 -> 0
B29: =SUM(B22:B28) -> 0 | C29: =SUM(C22:C28) -> 0 | D29: =SUM(D22:D28) -> 0 | E29: =SUM(E22:E28) -> 0 | F29: =SUM(F22:F28) -> 0 | G29: =SUM(G22:G28) -> 0 | H29: =SUM(H22:H28) -> 0 | I29: =SUM(I22:I28) -> 0 | ... AG29: =SUM(AG22:AG28) -> 0
A32: BANKING | B32: TOTAL
A33: - Cash | B33: =+Bank!AG8+Bank!AG9 -> 11.5
A34: - Cash Drops | B34: =+Bank!AG16 -> 0
A35: - Speedpoint | B35: =+Bank!AG24 -> 19855.45
A36: - Debtors | B36: =+Bank!AG43+Bank!AG44+Bank!AG45 -> 0
A37: - EFT | B37: =+Bank!AG52 -> 0
A38: - Loyalty | B38: =+Bank!AG58 -> 0
A39: - To Settle | B39: =+Bank!AG64 -> 0
A40: - Petty Cash | B40: =-SUM('Petty Cash Report'!B22:AF22) -> 0
A41: - TOTAL BANKING | B41: =SUM(B33:B40) -> 19866.95
A42: - SALES B/FWD | B42: =+B18 -> 0
A43: - OVER / (Under) | B43: =+B41-B42 -> 19866.95

Sheet Dashboard-Performance
B1: =+Input!A1 -> FUEL ROCK (PTY) LTD
B3: Monthly Dashboard | T3: =+Input!B6 -> 46143
B5: Liters Sold: Diesel
O6: LTS SOLD
B7: =+Summary!B7 -> 1659.39 | G7: FUEL RATIOS
B9: Target Litres For The Month | C9: =+'Dashboard-Fuel'!L136 -> 0
B10: As A % Of Target | C10: =+B7/C9 -> #DIV/0!
B12: Liters Sold: ULP 93
B14: =+Summary!C7 -> 40.06
B16: Target Litres For The Month | C16: =+'Dashboard-Fuel'!T136 -> 0
B17: As A % Of Target | C17: =+B14/C16 -> #DIV/0!
B19: Liters Sold: ULP 93
F20: CASHIER SHORTG
B21: =+Summary!D7 -> 1920.7
B23: Target Litres For The Month | C23: =+'Dashboard-Fuel'!P136 -> 0
B24: As A % Of Target | C24: =+B21/C23 -> #DIV/0!
B26: TOTAL LITRES SOLD
B28: =+B7+B14+B21 -> 3620.15
B30: Target Litres For The Month | C30: =+C9+C16+C23 -> 0
B31: As A % Of Target | C31: =+B28/C30 -> #DIV/0!
B33: Quickshop Sales
B35: =+Summary!B22+Summary!B23+Summary!B24+Summary!B28 -> 0
B37: Target Sales For The Month | C37: =+'Dashboard-Retail'!K100+'Dashboard-Retail'!P100 -> 0
B38: As A % Of Target | C38: =+B35/C37 -> #DIV/0!
B40: Cashier Shortages
B43: =+'Cashiers Report'!I37 -> 28206.04

Sheet Dashboard-Fuel
A1: =+Input!B2 -> ENGEN JETPARK
A3: Dashboard: Fuel | B3: =+Input!B6 -> 46143
A104: LITRES SOLD BY GRADE | B104: Diesel | C104: ULP: 95 | D104: ULP: 93 | E104: TOTAL | K104: Diesel | L104: Budget | O104: ULP: 95 | P104: Budget | S104: ULP: 93 | T104: Budget | V104: Budget
A105: 1 | B105: =+'1'!I12 -> 1659.39 | C105: =+'1'!J12 -> 1920.7 | D105: =+'1'!K12 -> 40.06 | E105: =SUM(B105:D105) -> 3620.15 | H105: =+Input!B10 -> Friday | J105: =+A105 -> 1 | K105: =+B105 -> 1659.39 | N105: =+J105 -> 1 | O105: =+C105 -> 1920.7 | R105: =+J105 -> 1 | S105: =+D105 -> 40.06 | V105: =+L105+P105+T105 -> 0
A106: =+A105+1 -> 2 | B106: =+'2'!I12 -> 0 | C106: =+'2'!J12 -> 0 | D106: =+'2'!K12 -> 0 | E106: =SUM(B106:D106) -> 0 | H106: =+Input!B11 -> Saturday | J106: =+A106 -> 2 | K106: =+B106 -> 0 | N106: =+J106 -> 2 | O106: =+C106 -> 0 | R106: =+J106 -> 2 | S106: =+D106 -> 0 | V106: =+L106+P106+T106 -> 0
A107: =+A106+1 -> 3 | B107: =+'3'!I12 -> 0 | C107: =+'3'!J12 -> 0 | D107: =+'3'!K12 -> 0 | E107: =SUM(B107:D107) -> 0 | H107: =+Input!B12 -> Sunday | J107: =+A107 -> 3 | K107: =+B107 -> 0 | N107: =+J107 -> 3 | O107: =+C107 -> 0 | R107: =+J107 -> 3 | S107: =+D107 -> 0 | V107: =+L107+P107+T107 -> 0
A108: =+A107+1 -> 4 | B108: =+'4'!I12 -> 0 | C108: =+'4'!J12 -> 0 | D108: =+'4'!K12 -> 0 | E108: =SUM(B108:D108) -> 0 | H108: =+Input!B13 -> Monday | J108: =+A108 -> 4 | K108: =+B108 -> 0 | N108: =+J108 -> 4 | O108: =+C108 -> 0 | R108: =+J108 -> 4 | S108: =+D108 -> 0 | V108: =+L108+P108+T108 -> 0
A109: =+A108+1 -> 5 | B109: =+'5'!I12 -> 0 | C109: =+'5'!J12 -> 0 | D109: =+'5'!K12 -> 0 | E109: =SUM(B109:D109) -> 0 | H109: =+Input!B14 -> Tuesday | J109: =+A109 -> 5 | K109: =+B109 -> 0 | N109: =+J109 -> 5 | O109: =+C109 -> 0 | R109: =+J109 -> 5 | S109: =+D109 -> 0 | V109: =+L109+P109+T109 -> 0
A110: =+A109+1 -> 6 | B110: =+'6'!I12 -> 0 | C110: =+'6'!J12 -> 0 | D110: =+'6'!K12 -> 0 | E110: =SUM(B110:D110) -> 0 | H110: =+Input!B15 -> Wednesday | J110: =+A110 -> 6 | K110: =+B110 -> 0 | N110: =+J110 -> 6 | O110: =+C110 -> 0 | R110: =+J110 -> 6 | S110: =+D110 -> 0 | V110: =+L110+P110+T110 -> 0
A111: =+A110+1 -> 7 | B111: =+'7'!I12 -> 0 | C111: =+'7'!J12 -> 0 | D111: =+'7'!K12 -> 0 | E111: =SUM(B111:D111) -> 0 | H111: =+Input!B16 -> Thursday | J111: =+A111 -> 7 | K111: =+B111 -> 0 | N111: =+J111 -> 7 | O111: =+C111 -> 0 | R111: =+J111 -> 7 | S111: =+D111 -> 0 | V111: =+L111+P111+T111 -> 0
A112: =+A111+1 -> 8 | B112: =+'8'!I12 -> 0 | C112: =+'8'!J12 -> 0 | D112: =+'8'!K12 -> 0 | E112: =SUM(B112:D112) -> 0 | H112: =+Input!B17 -> Friday | J112: =+A112 -> 8 | K112: =+B112 -> 0 | N112: =+J112 -> 8 | O112: =+C112 -> 0 | R112: =+J112 -> 8 | S112: =+D112 -> 0 | V112: =+L112+P112+T112 -> 0
A113: =+A112+1 -> 9 | B113: =+'9'!I12 -> 0 | C113: =+'9'!J12 -> 0 | D113: =+'9'!K12 -> 0 | E113: =SUM(B113:D113) -> 0 | H113: =+Input!B18 -> Saturday | J113: =+A113 -> 9 | K113: =+B113 -> 0 | N113: =+J113 -> 9 | O113: =+C113 -> 0 | R113: =+J113 -> 9 | S113: =+D113 -> 0 | V113: =+L113+P113+T113 -> 0
A114: =+A113+1 -> 10 | B114: =+'10'!I12 -> 0 | C114: =+'10'!J12 -> 0 | D114: =+'10'!K12 -> 0 | E114: =SUM(B114:D114) -> 0 | H114: =+Input!B19 -> Sunday | J114: =+A114 -> 10 | K114: =+B114 -> 0 | N114: =+J114 -> 10 | O114: =+C114 -> 0 | R114: =+J114 -> 10 | S114: =+D114 -> 0 | V114: =+L114+P114+T114 -> 0
A115: =+A114+1 -> 11 | B115: =+'11'!I12 -> 0 | C115: =+'11'!J12 -> 0 | D115: =+'11'!K12 -> 0 | E115: =SUM(B115:D115) -> 0 | H115: =+Input!B20 -> Monday | J115: =+A115 -> 11 | K115: =+B115 -> 0 | N115: =+J115 -> 11 | O115: =+C115 -> 0 | R115: =+J115 -> 11 | S115: =+D115 -> 0 | V115: =+L115+P115+T115 -> 0
A116: =+A115+1 -> 12 | B116: =+'12'!I12 -> 0 | C116: =+'12'!J12 -> 0 | D116: =+'12'!K12 -> 0 | E116: =SUM(B116:D116) -> 0 | H116: =+Input!B21 -> Tuesday | J116: =+A116 -> 12 | K116: =+B116 -> 0 | N116: =+J116 -> 12 | O116: =+C116 -> 0 | R116: =+J116 -> 12 | S116: =+D116 -> 0 | V116: =+L116+P116+T116 -> 0
A117: =+A116+1 -> 13 | B117: =+'13'!I12 -> 0 | C117: =+'13'!J12 -> 0 | D117: =+'13'!K12 -> 0 | E117: =SUM(B117:D117) -> 0 | H117: =+Input!B22 -> Wednesday | J117: =+A117 -> 13 | K117: =+B117 -> 0 | N117: =+J117 -> 13 | O117: =+C117 -> 0 | R117: =+J117 -> 13 | S117: =+D117 -> 0 | V117: =+L117+P117+T117 -> 0
A118: =+A117+1 -> 14 | B118: =+'14'!I12 -> 0 | C118: =+'14'!J12 -> 0 | D118: =+'14'!K12 -> 0 | E118: =SUM(B118:D118) -> 0 | H118: =+Input!B23 -> Thursday | J118: =+A118 -> 14 | K118: =+B118 -> 0 | N118: =+J118 -> 14 | O118: =+C118 -> 0 | R118: =+J118 -> 14 | S118: =+D118 -> 0 | V118: =+L118+P118+T118 -> 0
A119: =+A118+1 -> 15 | B119: =+'15'!I12 -> 0 | C119: =+'15'!J12 -> 0 | D119: =+'15'!K12 -> 0 | E119: =SUM(B119:D119) -> 0 | H119: =+Input!B24 -> Friday | J119: =+A119 -> 15 | K119: =+B119 -> 0 | N119: =+J119 -> 15 | O119: =+C119 -> 0 | R119: =+J119 -> 15 | S119: =+D119 -> 0 | V119: =+L119+P119+T119 -> 0
A120: =+A119+1 -> 16 | B120: =+'16'!I12 -> 0 | C120: =+'16'!J12 -> 0 | D120: =+'16'!K12 -> 0 | E120: =SUM(B120:D120) -> 0 | H120: =+Input!B25 -> Saturday | J120: =+A120 -> 16 | K120: =+B120 -> 0 | N120: =+J120 -> 16 | O120: =+C120 -> 0 | R120: =+J120 -> 16 | S120: =+D120 -> 0 | V120: =+L120+P120+T120 -> 0
A121: =+A120+1 -> 17 | B121: =+'17'!I12 -> 0 | C121: =+'17'!J12 -> 0 | D121: =+'17'!K12 -> 0 | E121: =SUM(B121:D121) -> 0 | H121: =+Input!B26 -> Sunday | J121: =+A121 -> 17 | K121: =+B121 -> 0 | N121: =+J121 -> 17 | O121: =+C121 -> 0 | R121: =+J121 -> 17 | S121: =+D121 -> 0 | V121: =+L121+P121+T121 -> 0
A122: =+A121+1 -> 18 | B122: =+'18'!I12 -> 0 | C122: =+'18'!J12 -> 0 | D122: =+'18'!K12 -> 0 | E122: =SUM(B122:D122) -> 0 | H122: =+Input!B27 -> Monday | J122: =+A122 -> 18 | K122: =+B122 -> 0 | N122: =+J122 -> 18 | O122: =+C122 -> 0 | R122: =+J122 -> 18 | S122: =+D122 -> 0 | V122: =+L122+P122+T122 -> 0
A123: =+A122+1 -> 19 | B123: =+'19'!I12 -> 0 | C123: =+'19'!J12 -> 0 | D123: =+'19'!K12 -> 0 | E123: =SUM(B123:D123) -> 0 | H123: =+Input!B28 -> Tuesday | J123: =+A123 -> 19 | K123: =+B123 -> 0 | N123: =+J123 -> 19 | O123: =+C123 -> 0 | R123: =+J123 -> 19 | S123: =+D123 -> 0 | V123: =+L123+P123+T123 -> 0
A124: =+A123+1 -> 20 | B124: =+'20'!I12 -> 0 | C124: =+'20'!J12 -> 0 | D124: =+'20'!K12 -> 0 | E124: =SUM(B124:D124) -> 0 | H124: =+Input!B29 -> Wednesday | J124: =+A124 -> 20 | K124: =+B124 -> 0 | N124: =+J124 -> 20 | O124: =+C124 -> 0 | R124: =+J124 -> 20 | S124: =+D124 -> 0 | V124: =+L124+P124+T124 -> 0
A125: =+A124+1 -> 21 | B125: =+'21'!I12 -> 0 | C125: =+'21'!J12 -> 0 | D125: =+'21'!K12 -> 0 | E125: =SUM(B125:D125) -> 0 | H125: =+Input!B30 -> Thursday | J125: =+A125 -> 21 | K125: =+B125 -> 0 | N125: =+J125 -> 21 | O125: =+C125 -> 0 | R125: =+J125 -> 21 | S125: =+D125 -> 0 | V125: =+L125+P125+T125 -> 0
A126: =+A125+1 -> 22 | B126: =+'22'!I12 -> 0 | C126: =+'22'!J12 -> 0 | D126: =+'22'!K12 -> 0 | E126: =SUM(B126:D126) -> 0 | H126: =+Input!B31 -> Friday | J126: =+A126 -> 22 | K126: =+B126 -> 0 | N126: =+J126 -> 22 | O126: =+C126 -> 0 | R126: =+J126 -> 22 | S126: =+D126 -> 0 | V126: =+L126+P126+T126 -> 0
A127: =+A126+1 -> 23 | B127: =+'23'!I12 -> 0 | C127: =+'23'!J12 -> 0 | D127: =+'23'!K12 -> 0 | E127: =SUM(B127:D127) -> 0 | H127: =+Input!B32 -> Saturday | J127: =+A127 -> 23 | K127: =+B127 -> 0 | N127: =+J127 -> 23 | O127: =+C127 -> 0 | R127: =+J127 -> 23 | S127: =+D127 -> 0 | V127: =+L127+P127+T127 -> 0
A128: =+A127+1 -> 24 | B128: =+'24'!I12 -> 0 | C128: =+'24'!J12 -> 0 | D128: =+'24'!K12 -> 0 | E128: =SUM(B128:D128) -> 0 | H128: =+Input!B33 -> Sunday | J128: =+A128 -> 24 | K128: =+B128 -> 0 | N128: =+J128 -> 24 | O128: =+C128 -> 0 | R128: =+J128 -> 24 | S128: =+D128 -> 0 | V128: =+L128+P128+T128 -> 0
A129: =+A128+1 -> 25 | B129: =+'25'!I12 -> 0 | C129: =+'25'!J12 -> 0 | D129: =+'25'!K12 -> 0 | E129: =SUM(B129:D129) -> 0 | H129: =+Input!B34 -> Monday | J129: =+A129 -> 25 | K129: =+B129 -> 0 | N129: =+J129 -> 25 | O129: =+C129 -> 0 | R129: =+J129 -> 25 | S129: =+D129 -> 0 | V129: =+L129+P129+T129 -> 0
A130: =+A129+1 -> 26 | B130: =+'26'!I12 -> 0 | C130: =+'26'!J12 -> 0 | D130: =+'26'!K12 -> 0 | E130: =SUM(B130:D130) -> 0 | H130: =+Input!B35 -> Tuesday | J130: =+A130 -> 26 | K130: =+B130 -> 0 | N130: =+J130 -> 26 | O130: =+C130 -> 0 | R130: =+J130 -> 26 | S130: =+D130 -> 0 | V130: =+L130+P130+T130 -> 0
A131: =+A130+1 -> 27 | B131: =+'27'!I12 -> 0 | C131: =+'27'!J12 -> 0 | D131: =+'27'!K12 -> 0 | E131: =SUM(B131:D131) -> 0 | H131: =+Input!B36 -> Wednesday | J131: =+A131 -> 27 | K131: =+B131 -> 0 | N131: =+J131 -> 27 | O131: =+C131 -> 0 | R131: =+J131 -> 27 | S131: =+D131 -> 0 | V131: =+L131+P131+T131 -> 0
A132: =+A131+1 -> 28 | B132: =+'28'!I12 -> 0 | C132: =+'28'!J12 -> 0 | D132: =+'28'!K12 -> 0 | E132: =SUM(B132:D132) -> 0 | H132: =+Input!B37 -> Thursday | J132: =+A132 -> 28 | K132: =+B132 -> 0 | N132: =+J132 -> 28 | O132: =+C132 -> 0 | R132: =+J132 -> 28 | S132: =+D132 -> 0 | V132: =+L132+P132+T132 -> 0
A133: =+A132+1 -> 29 | B133: =+'29'!I12 -> 0 | C133: =+'29'!J12 -> 0 | D133: =+'29'!K12 -> 0 | E133: =SUM(B133:D133) -> 0 | H133: =+Input!B38 -> Friday | J133: =+A133 -> 29 | K133: =+B133 -> 0 | N133: =+J133 -> 29 | O133: =+C133 -> 0 | R133: =+J133 -> 29 | S133: =+D133 -> 0 | V133: =+L133+P133+T133 -> 0
A134: =+A133+1 -> 30 | B134: =+'30'!I12 -> 0 | C134: =+'30'!J12 -> 0 | D134: =+'30'!K12 -> 0 | E134: =SUM(B134:D134) -> 0 | H134: =+Input!B39 -> Saturday | J134: =+A134 -> 30 | K134: =+B134 -> 0 | N134: =+J134 -> 30 | O134: =+C134 -> 0 | R134: =+J134 -> 30 | S134: =+D134 -> 0 | V134: =+L134+P134+T134 -> 0
A135: =+A134+1 -> 31 | B135: =+'31'!I12 -> 0 | C135: =+'31'!J12 -> 0 | D135: =+'31'!K12 -> 0 | E135: =SUM(B135:D135) -> 0 | H135: =+Input!B40 -> Sunday | J135: =+A135 -> 31 | K135: =+B135 -> 0 | N135: =+J135 -> 31 | O135: =+C135 -> 0 | R135: =+J135 -> 31 | S135: =+D135 -> 0 | V135: =+L135+P135+T135 -> 0
B136: =SUM(B105:B135) -> 1659.39 | C136: =SUM(C105:C135) -> 1920.7 | D136: =SUM(D105:D135) -> 40.06 | E136: =SUM(E105:E135) -> 3620.15 | L136: =SUM(L105:L135) -> 0 | P136: =SUM(P105:P135) -> 0 | T136: =SUM(T105:T135) -> 0 | V136: =SUM(V105:V135) -> 0
A139: CLOSING STOCK | B139: Diesel | C139: ULP: 95 | D139: ULP: 93 | E139: TOTAL
A140: 1 | B140: =+'SS26'!W29 -> 0 | C140: =+'SS26'!W65 -> 0 | D140: =+'SS26'!G101 -> 0 | E140: =SUM(B140:D140) -> 0
A141: =+A140+1 -> 2 | B141: =+'SS26'!W30 -> 0 | C141: =+'SS26'!W66 -> 0 | D141: =+'SS26'!G102 -> 0 | E141: =SUM(B141:D141) -> 0
A142: =+A141+1 -> 3 | B142: =+'SS26'!W31 -> 0 | C142: =+'SS26'!W67 -> 0 | D142: =+'SS26'!G103 -> 0 | E142: =SUM(B142:D142) -> 0
A143: =+A142+1 -> 4 | B143: =+'SS26'!W32 -> 0 | C143: =+'SS26'!W68 -> 0 | D143: =+'SS26'!G104 -> 0 | E143: =SUM(B143:D143) -> 0
...

Sheet Dashboard-Retail
A1: =+Input!B2 -> ENGEN JETPARK
A3: Dashboard: Retail | B3: =+Input!B6 -> 46143
A60: SALES BY DIVISION | B60: 1 | C60: =+B60+1 -> 2 | D60: =+C60+1 -> 3 | E60: =+D60+1 -> 4 | F60: =+E60+1 -> 5 | G60: =+F60+1 -> 6 | H60: =+G60+1 -> 7 | I60: =+H60+1 -> 8 | J60: =+I60+1 -> 9 | ... AF60: =+AE60+1 -> 31
A61: - Bakery | B61: =SUM(Summary!C22:C24) -> 0 | C61: =SUM(Summary!D22:D24) -> 0 | D61: =SUM(Summary!E22:E24) -> 0 | E61: =SUM(Summary!F22:F24) -> 0 | F61: =SUM(Summary!G22:G24) -> 0 | G61: =SUM(Summary!H22:H24) -> 0 | H61: =SUM(Summary!I22:I24) -> 0 | I61: =SUM(Summary!J22:J24) -> 0 | ... AF61: =SUM(Summary!AG22:AG24) -> 0
A62: - VV | B62: =+Summary!C27 -> 0 | C62: =+Summary!D27 -> 0 | D62: =+Summary!E27 -> 0 | E62: =+Summary!F27 -> 0 | F62: =+Summary!G27 -> 0 | G62: =+Summary!H27 -> 0 | H62: =+Summary!I27 -> 0 | I62: =+Summary!J27 -> 0 | ... AF62: =+Summary!AG27 -> 0
A63: - Quickshop | B63: =+Summary!C28 -> 0 | C63: =+Summary!D28 -> 0 | D63: =+Summary!E28 -> 0 | E63: =+Summary!F28 -> 0 | F63: =+Summary!G28 -> 0 | G63: =+Summary!H28 -> 0 | H63: =+Summary!I28 -> 0 | I63: =+Summary!J28 -> 0 | ... AF63: =+Summary!AG28 -> 0
B64: =SUM(B61:B63) -> 0 | C64: =SUM(C61:C63) -> 0 | D64: =SUM(D61:D63) -> 0 | E64: =SUM(E61:E63) -> 0 | F64: =SUM(F61:F63) -> 0 | G64: =SUM(G61:G63) -> 0 | H64: =SUM(H61:H63) -> 0 | I64: =SUM(I61:I63) -> 0 | ... AF64: =SUM(AF61:AF63) -> 0
J67: Bakery | O67: C/Store
B68: Lts | D68: Bakery | F68: Conven | J68: Actual | K68: Budget | O68: Actual | P68: Budget
A69: 1 | B69: =+'Dashboard-Fuel'!V105 -> 0 | C69: 0.3 | D69: =+B69*C69 -> 0 | E69: 0.85 | F69: =+B69*E69 -> 0 | I69: =+A69 -> 1 | J69: =+B61 -> 0 | K69: =+D69 -> 0 | N69: =+I69 -> 1 | O69: =+B63 -> 0 | P69: =+F69 -> 0
A70: =+A69+1 -> 2 | B70: =+'Dashboard-Fuel'!V106 -> 0 | C70: =+$C$69 -> 0.3 | D70: =+B70*C70 -> 0 | E70: =+$E$69 -> 0.85 | F70: =+B70*E70 -> 0 | I70: =+A70 -> 2 | J70: =+C61 -> 0 | K70: =+D70 -> 0 | N70: =+I70 -> 2 | O70: =+C63 -> 0 | P70: 0
A71: =+A70+1 -> 3 | B71: =+'Dashboard-Fuel'!V107 -> 0 | C71: =+$C$69 -> 0.3 | D71: =+B71*C71 -> 0 | E71: =+$E$69 -> 0.85 | F71: =+B71*E71 -> 0 | I71: =+A71 -> 3 | J71: =+D61 -> 0 | K71: =+D71 -> 0 | N71: =+I71 -> 3 | O71: =+D63 -> 0 | P71: =+F71 -> 0
A72: =+A71+1 -> 4 | B72: =+'Dashboard-Fuel'!V108 -> 0 | C72: =+$C$69 -> 0.3 | D72: =+B72*C72 -> 0 | E72: =+$E$69 -> 0.85 | F72: =+B72*E72 -> 0 | I72: =+A72 -> 4 | J72: =+E61 -> 0 | K72: =+D72 -> 0 | N72: =+I72 -> 4 | O72: =+E63 -> 0 | P72: =+F72 -> 0
A73: =+A72+1 -> 5 | B73: =+'Dashboard-Fuel'!V109 -> 0 | C73: =+$C$69 -> 0.3 | D73: =+B73*C73 -> 0 | E73: =+$E$69 -> 0.85 | F73: =+B73*E73 -> 0 | I73: =+A73 -> 5 | J73: =+F61 -> 0 | K73: =+D73 -> 0 | N73: =+I73 -> 5 | O73: =+F63 -> 0 | P73: =+F73 -> 0
A74: =+A73+1 -> 6 | B74: =+'Dashboard-Fuel'!V110 -> 0 | C74: =+$C$69 -> 0.3 | D74: =+B74*C74 -> 0 | E74: =+$E$69 -> 0.85 | F74: =+B74*E74 -> 0 | I74: =+A74 -> 6 | J74: =+G61 -> 0 | K74: =+D74 -> 0 | N74: =+I74 -> 6 | O74: =+G63 -> 0 | P74: =+F74 -> 0
A75: =+A74+1 -> 7 | B75: =+'Dashboard-Fuel'!V111 -> 0 | C75: =+$C$69 -> 0.3 | D75: =+B75*C75 -> 0 | E75: =+$E$69 -> 0.85 | F75: =+B75*E75 -> 0 | I75: =+A75 -> 7 | J75: =+H61 -> 0 | K75: =+D75 -> 0 | N75: =+I75 -> 7 | O75: =+H63 -> 0 | P75: =+F75 -> 0
A76: =+A75+1 -> 8 | B76: =+'Dashboard-Fuel'!V112 -> 0 | C76: =+$C$69 -> 0.3 | D76: =+B76*C76 -> 0 | E76: =+$E$69 -> 0.85 | F76: =+B76*E76 -> 0 | I76: =+A76 -> 8 | J76: =+I61 -> 0 | K76: =+D76 -> 0 | N76: =+I76 -> 8 | O76: =+I63 -> 0 | P76: =+F76 -> 0
A77: =+A76+1 -> 9 | B77: =+'Dashboard-Fuel'!V113 -> 0 | C77: =+$C$69 -> 0.3 | D77: =+B77*C77 -> 0 | E77: =+$E$69 -> 0.85 | F77: =+B77*E77 -> 0 | I77: =+A77 -> 9 | J77: =+J61 -> 0 | K77: =+D77 -> 0 | N77: =+I77 -> 9 | O77: =+J63 -> 0 | P77: =+F77 -> 0
A78: =+A77+1 -> 10 | B78: =+'Dashboard-Fuel'!V114 -> 0 | C78: =+$C$69 -> 0.3 | D78: =+B78*C78 -> 0 | E78: =+$E$69 -> 0.85 | F78: =+B78*E78 -> 0 | I78: =+A78 -> 10 | J78: =+K61 -> 0 | K78: =+D78 -> 0 | N78: =+I78 -> 10 | O78: =+K63 -> 0 | P78: =+F78 -> 0
A79: =+A78+1 -> 11 | B79: =+'Dashboard-Fuel'!V115 -> 0 | C79: =+$C$69 -> 0.3 | D79: =+B79*C79 -> 0 | E79: =+$E$69 -> 0.85 | F79: =+B79*E79 -> 0 | I79: =+A79 -> 11 | J79: =+L61 -> 0 | K79: =+D79 -> 0 | N79: =+I79 -> 11 | O79: =+L63 -> 0 | P79: =+F79 -> 0
A80: =+A79+1 -> 12 | B80: =+'Dashboard-Fuel'!V116 -> 0 | C80: =+$C$69 -> 0.3 | D80: =+B80*C80 -> 0 | E80: =+$E$69 -> 0.85 | F80: =+B80*E80 -> 0 | I80: =+A80 -> 12 | J80: =+M61 -> 0 | K80: =+D80 -> 0 | N80: =+I80 -> 12 | O80: =+M63 -> 0 | P80: =+F80 -> 0
A81: =+A80+1 -> 13 | B81: =+'Dashboard-Fuel'!V117 -> 0 | C81: =+$C$69 -> 0.3 | D81: =+B81*C81 -> 0 | E81: =+$E$69 -> 0.85 | F81: =+B81*E81 -> 0 | I81: =+A81 -> 13 | J81: =+N61 -> 0 | K81: =+D81 -> 0 | N81: =+I81 -> 13 | O81: =+N63 -> 0 | P81: =+F81 -> 0
A82: =+A81+1 -> 14 | B82: =+'Dashboard-Fuel'!V118 -> 0 | C82: =+$C$69 -> 0.3 | D82: =+B82*C82 -> 0 | E82: =+$E$69 -> 0.85 | F82: =+B82*E82 -> 0 | I82: =+A82 -> 14 | J82: =+O61 -> 0 | K82: =+D82 -> 0 | N82: =+I82 -> 14 | O82: =+O63 -> 0 | P82: =+F82 -> 0
A83: =+A82+1 -> 15 | B83: =+'Dashboard-Fuel'!V119 -> 0 | C83: =+$C$69 -> 0.3 | D83: =+B83*C83 -> 0 | E83: =+$E$69 -> 0.85 | F83: =+B83*E83 -> 0 | I83: =+A83 -> 15 | J83: =+P61 -> 0 | K83: =+D83 -> 0 | N83: =+I83 -> 15 | O83: =+P63 -> 0 | P83: =+F83 -> 0
A84: =+A83+1 -> 16 | B84: =+'Dashboard-Fuel'!V120 -> 0 | C84: =+$C$69 -> 0.3 | D84: =+B84*C84 -> 0 | E84: =+$E$69 -> 0.85 | F84: =+B84*E84 -> 0 | I84: =+A84 -> 16 | J84: =+Q61 -> 0 | K84: =+D84 -> 0 | N84: =+I84 -> 16 | O84: =+Q63 -> 0 | P84: =+F84 -> 0
A85: =+A84+1 -> 17 | B85: =+'Dashboard-Fuel'!V121 -> 0 | C85: =+$C$69 -> 0.3 | D85: =+B85*C85 -> 0 | E85: =+$E$69 -> 0.85 | F85: =+B85*E85 -> 0 | I85: =+A85 -> 17 | J85: =+R61 -> 0 | K85: =+D85 -> 0 | N85: =+I85 -> 17 | O85: =+R63 -> 0 | P85: =+F85 -> 0
A86: =+A85+1 -> 18 | B86: =+'Dashboard-Fuel'!V122 -> 0 | C86: =+$C$69 -> 0.3 | D86: =+B86*C86 -> 0 | E86: =+$E$69 -> 0.85 | F86: =+B86*E86 -> 0 | I86: =+A86 -> 18 | J86: =+S61 -> 0 | K86: =+D86 -> 0 | N86: =+I86 -> 18 | O86: =+S63 -> 0 | P86: =+F86 -> 0
A87: =+A86+1 -> 19 | B87: =+'Dashboard-Fuel'!V123 -> 0 | C87: =+$C$69 -> 0.3 | D87: =+B87*C87 -> 0 | E87: =+$E$69 -> 0.85 | F87: =+B87*E87 -> 0 | I87: =+A87 -> 19 | J87: =+T61 -> 0 | K87: =+D87 -> 0 | N87: =+I87 -> 19 | O87: =+T63 -> 0 | P87: =+F87 -> 0
A88: =+A87+1 -> 20 | B88: =+'Dashboard-Fuel'!V124 -> 0 | C88: =+$C$69 -> 0.3 | D88: =+B88*C88 -> 0 | E88: =+$E$69 -> 0.85 | F88: =+B88*E88 -> 0 | I88: =+A88 -> 20 | J88: =+U61 -> 0 | K88: =+D88 -> 0 | N88: =+I88 -> 20 | O88: =+U63 -> 0 | P88: =+F88 -> 0
A89: =+A88+1 -> 21 | B89: =+'Dashboard-Fuel'!V125 -> 0 | C89: =+$C$69 -> 0.3 | D89: =+B89*C89 -> 0 | E89: =+$E$69 -> 0.85 | F89: =+B89*E89 -> 0 | I89: =+A89 -> 21 | J89: =+V61 -> 0 | K89: =+D89 -> 0 | N89: =+I89 -> 21 | O89: =+V63 -> 0 | P89: =+F89 -> 0
A90: =+A89+1 -> 22 | B90: =+'Dashboard-Fuel'!V126 -> 0 | C90: =+$C$69 -> 0.3 | D90: =+B90*C90 -> 0 | E90: =+$E$69 -> 0.85 | F90: =+B90*E90 -> 0 | I90: =+A90 -> 22 | J90: =+W61 -> 0 | K90: =+D90 -> 0 | N90: =+I90 -> 22 | O90: =+W63 -> 0 | P90: =+F90 -> 0
A91: =+A90+1 -> 23 | B91: =+'Dashboard-Fuel'!V127 -> 0 | C91: =+$C$69 -> 0.3 | D91: =+B91*C91 -> 0 | E91: =+$E$69 -> 0.85 | F91: =+B91*E91 -> 0 | I91: =+A91 -> 23 | J91: =+X61 -> 0 | K91: =+D91 -> 0 | N91: =+I91 -> 23 | O91: =+X63 -> 0 | P91: =+F91 -> 0
A92: =+A91+1 -> 24 | B92: =+'Dashboard-Fuel'!V128 -> 0 | C92: =+$C$69 -> 0.3 | D92: =+B92*C92 -> 0 | E92: =+$E$69 -> 0.85 | F92: =+B92*E92 -> 0 | I92: =+A92 -> 24 | J92: =+Y61 -> 0 | K92: =+D92 -> 0 | N92: =+I92 -> 24 | O92: =+Y63 -> 0 | P92: =+F92 -> 0
A93: =+A92+1 -> 25 | B93: =+'Dashboard-Fuel'!V129 -> 0 | C93: =+$C$69 -> 0.3 | D93: =+B93*C93 -> 0 | E93: =+$E$69 -> 0.85 | F93: =+B93*E93 -> 0 | I93: =+A93 -> 25 | J93: =+Z61 -> 0 | K93: =+D93 -> 0 | N93: =+I93 -> 25 | O93: =+Z63 -> 0 | P93: =+F93 -> 0
A94: =+A93+1 -> 26 | B94: =+'Dashboard-Fuel'!V130 -> 0 | C94: =+$C$69 -> 0.3 | D94: =+B94*C94 -> 0 | E94: =+$E$69 -> 0.85 | F94: =+B94*E94 -> 0 | I94: =+A94 -> 26 | J94: =+AA61 -> 0 | K94: =+D94 -> 0 | N94: =+I94 -> 26 | O94: =+AA63 -> 0 | P94: =+F94 -> 0
A95: =+A94+1 -> 27 | B95: =+'Dashboard-Fuel'!V131 -> 0 | C95: =+$C$69 -> 0.3 | D95: =+B95*C95 -> 0 | E95: =+$E$69 -> 0.85 | F95: =+B95*E95 -> 0 | I95: =+A95 -> 27 | J95: =+AB61 -> 0 | K95: =+D95 -> 0 | N95: =+I95 -> 27 | O95: =+AB63 -> 0 | P95: =+F95 -> 0
A96: =+A95+1 -> 28 | B96: =+'Dashboard-Fuel'!V132 -> 0 | C96: =+$C$69 -> 0.3 | D96: =+B96*C96 -> 0 | E96: =+$E$69 -> 0.85 | F96: =+B96*E96 -> 0 | I96: =+A96 -> 28 | J96: =+AC61 -> 0 | K96: =+D96 -> 0 | N96: =+I96 -> 28 | O96: =+AC63 -> 0 | P96: =+F96 -> 0
A97: =+A96+1 -> 29 | B97: =+'Dashboard-Fuel'!V133 -> 0 | C97: =+$C$69 -> 0.3 | D97: =+B97*C97 -> 0 | E97: =+$E$69 -> 0.85 | F97: =+B97*E97 -> 0 | I97: =+A97 -> 29 | J97: =+AD61 -> 0 | K97: =+D97 -> 0 | N97: =+I97 -> 29 | O97: =+AD63 -> 0 | P97: =+F97 -> 0
A98: =+A97+1 -> 30 | B98: =+'Dashboard-Fuel'!V134 -> 0 | C98: =+$C$69 -> 0.3 | D98: =+B98*C98 -> 0 | E98: =+$E$69 -> 0.85 | F98: =+B98*E98 -> 0 | I98: =+A98 -> 30 | J98: =+AE61 -> 0 | K98: =+D98 -> 0 | N98: =+I98 -> 30 | O98: =+AE63 -> 0 | P98: =+F98 -> 0
A99: =+A98+1 -> 31 | B99: =+'Dashboard-Fuel'!V135 -> 0 | C99: =+$C$69 -> 0.3 | D99: =+B99*C99 -> 0 | E99: =+$E$69 -> 0.85 | F99: =+B99*E99 -> 0 | I99: =+A99 -> 31 | J99: =+AF61 -> 0 | K99: =+D99 -> 0 | N99: =+I99 -> 31 | O99: =+AF63 -> 0 | P99: =+F99 -> 0
...

Sheet Cashiers Report
A1: =+Input!B2 -> ENGEN JETPARK
A3: Cashiers Report | C3: =+Input!B6 -> 46143
A5: Day | B5: Date | C5: =+Input!B44 -> Mandla | D5: =+Input!C44 -> Caroline | E5: =+Input!D44 -> Siyabonga | F5: =+Input!E44 -> Thumelo | G5: =+Input!F44 -> Cashier 5 | H5: =+Input!G44 -> Cashier 6 | I5: TOTAL | J5: CT | K5: VARIANCE
A6: =+Input!B10 -> Friday | B6: =+Input!C10 -> 46143 | C6: =+'1'!B53 -> 33206.04 | D6: =+'1'!C53 -> -1000 | E6: =+'1'!D53 -> -1000 | F6: =+'1'!E53 -> -1000 | G6: =+'1'!F53 -> -1000 | H6: =+'1'!G53 -> -1000 | I6: =SUM(C6:H6) -> 28206.04 | J6: =+'1'!H53 -> 28206.04 | K6: =+J6-I6 -> 0
A7: =+Input!B11 -> Saturday | B7: =+Input!C11 -> 46144 | C7: =+'2'!B53 -> 0 | D7: =+'2'!C53 -> 0 | E7: =+'2'!D53 -> 0 | F7: =+'2'!E53 -> 0 | G7: =+'2'!F53 -> 0 | H7: =+'2'!G53 -> 0 | I7: =SUM(C7:H7) -> 0 | J7: =+'2'!H53 -> 0 | K7: =+J7-I7 -> 0
A8: =+Input!B12 -> Sunday | B8: =+Input!C12 -> 46145 | C8: =+'3'!B53 -> 0 | D8: =+'3'!C53 -> 0 | E8: =+'3'!D53 -> 0 | F8: =+'3'!E53 -> 0 | G8: =+'3'!F53 -> 0 | H8: =+'3'!G53 -> 0 | I8: =SUM(C8:H8) -> 0 | J8: =+'3'!H53 -> 0 | K8: =+J8-I8 -> 0
A9: =+Input!B13 -> Monday | B9: =+Input!C13 -> 46146 | C9: =+'4'!B53 -> 0 | D9: =+'4'!C53 -> 0 | E9: =+'4'!D53 -> 0 | F9: =+'4'!E53 -> 0 | G9: =+'4'!F53 -> 0 | H9: =+'4'!G53 -> 0 | I9: =SUM(C9:H9) -> 0 | J9: =+'4'!H53 -> 0 | K9: =+J9-I9 -> 0
A10: =+Input!B14 -> Tuesday | B10: =+Input!C14 -> 46147 | C10: =+'5'!B53 -> 0 | D10: =+'5'!C53 -> 0 | E10: =+'5'!D53 -> 0 | F10: =+'5'!E53 -> 0 | G10: =+'5'!F53 -> 0 | H10: =+'5'!G53 -> 0 | I10: =SUM(C10:H10) -> 0 | J10: =+'5'!H53 -> 0 | K10: =+J10-I10 -> 0
A11: =+Input!B15 -> Wednesday | B11: =+Input!C15 -> 46148 | C11: =+'6'!B53 -> 0 | D11: =+'6'!C53 -> 0 | E11: =+'6'!D53 -> 0 | F11: =+'6'!E53 -> 0 | G11: =+'6'!F53 -> 0 | H11: =+'6'!G53 -> 0 | I11: =SUM(C11:H11) -> 0 | J11: =+'6'!H53 -> 0 | K11: =+J11-I11 -> 0
A12: =+Input!B16 -> Thursday | B12: =+Input!C16 -> 46149 | C12: =+'7'!B53 -> 0 | D12: =+'7'!C53 -> 0 | E12: =+'7'!D53 -> 0 | F12: =+'7'!E53 -> 0 | G12: =+'7'!F53 -> 0 | H12: =+'7'!G53 -> 0 | I12: =SUM(C12:H12) -> 0 | J12: =+'7'!H53 -> 0 | K12: =+J12-I12 -> 0
A13: =+Input!B17 -> Friday | B13: =+Input!C17 -> 46150 | C13: =+'8'!B53 -> 0 | D13: =+'8'!C53 -> 0 | E13: =+'8'!D53 -> 0 | F13: =+'8'!E53 -> 0 | G13: =+'8'!F53 -> 0 | H13: =+'8'!G53 -> 0 | I13: =SUM(C13:H13) -> 0 | J13: =+'8'!H53 -> 0 | K13: =+J13-I13 -> 0
A14: =+Input!B18 -> Saturday | B14: =+Input!C18 -> 46151 | C14: =+'9'!B53 -> 0 | D14: =+'9'!C53 -> 0 | E14: =+'9'!D53 -> 0 | F14: =+'9'!E53 -> 0 | G14: =+'9'!F53 -> 0 | H14: =+'9'!G53 -> 0 | I14: =SUM(C14:H14) -> 0 | J14: =+'9'!H53 -> 0 | K14: =+J14-I14 -> 0
A15: =+Input!B19 -> Sunday | B15: =+Input!C19 -> 46152 | C15: =+'10'!B53 -> 0 | D15: =+'10'!C53 -> 0 | E15: =+'10'!D53 -> 0 | F15: =+'10'!E53 -> 0 | G15: =+'10'!F53 -> 0 | H15: =+'10'!G53 -> 0 | I15: =SUM(C15:H15) -> 0 | J15: =+'10'!H53 -> 0 | K15: =+J15-I15 -> 0
A16: =+Input!B20 -> Monday | B16: =+Input!C20 -> 46153 | C16: =+'11'!B53 -> 0 | D16: =+'11'!C53 -> 0 | E16: =+'11'!D53 -> 0 | F16: =+'11'!E53 -> 0 | G16: =+'11'!F53 -> 0 | H16: =+'11'!G53 -> 0 | I16: =SUM(C16:H16) -> 0 | J16: =+'11'!H53 -> 0 | K16: =+J16-I16 -> 0
A17: =+Input!B21 -> Tuesday | B17: =+Input!C21 -> 46154 | C17: =+'12'!B53 -> 0 | D17: =+'12'!C53 -> 0 | E17: =+'12'!D53 -> 0 | F17: =+'12'!E53 -> 0 | G17: =+'12'!F53 -> 0 | H17: =+'12'!G53 -> 0 | I17: =SUM(C17:H17) -> 0 | J17: =+'12'!H53 -> 0 | K17: =+J17-I17 -> 0
A18: =+Input!B22 -> Wednesday | B18: =+Input!C22 -> 46155 | C18: =+'13'!B53 -> 0 | D18: =+'13'!C53 -> 0 | E18: =+'13'!D53 -> 0 | F18: =+'13'!E53 -> 0 | G18: =+'13'!F53 -> 0 | H18: =+'13'!G53 -> 0 | I18: =SUM(C18:H18) -> 0 | J18: =+'13'!B53 -> 0 | K18: =+J18-I18 -> 0
A19: =+Input!B23 -> Thursday | B19: =+Input!C23 -> 46156 | C19: =+'14'!B53 -> 0 | D19: =+'14'!C53 -> 0 | E19: =+'14'!D53 -> 0 | F19: =+'14'!E53 -> 0 | G19: =+'14'!F53 -> 0 | H19: =+'14'!G53 -> 0 | I19: =SUM(C19:H19) -> 0 | J19: =+'14'!H53 -> 0 | K19: =+J19-I19 -> 0
A20: =+Input!B24 -> Friday | B20: =+Input!C24 -> 46157 | C20: =+'15'!B53 -> 0 | D20: =+'15'!C53 -> 0 | E20: =+'15'!D53 -> 0 | F20: =+'15'!E53 -> 0 | G20: =+'15'!F53 -> 0 | H20: =+'15'!G53 -> 0 | I20: =SUM(C20:H20) -> 0 | J20: =+'15'!H53 -> 0 | K20: =+J20-I20 -> 0
A21: =+Input!B25 -> Saturday | B21: =+Input!C25 -> 46158 | C21: =+'16'!B53 -> 0 | D21: =+'16'!C53 -> 0 | E21: =+'16'!D53 -> 0 | F21: =+'16'!E53 -> 0 | G21: =+'16'!F53 -> 0 | H21: =+'16'!G53 -> 0 | I21: =SUM(C21:H21) -> 0 | J21: =+'16'!H53 -> 0 | K21: =+J21-I21 -> 0
A22: =+Input!B26 -> Sunday | B22: =+Input!C26 -> 46159 | C22: =+'17'!B53 -> 0 | D22: =+'17'!C53 -> 0 | E22: =+'17'!D53 -> 0 | F22: =+'17'!E53 -> 0 | G22: =+'17'!F53 -> 0 | H22: =+'17'!G53 -> 0 | I22: =SUM(C22:H22) -> 0 | J22: =+'17'!H53 -> 0 | K22: =+J22-I22 -> 0
A23: =+Input!B27 -> Monday | B23: =+Input!C27 -> 46160 | C23: =+'18'!B53 -> 0 | D23: =+'18'!C53 -> 0 | E23: =+'18'!D53 -> 0 | F23: =+'18'!E53 -> 0 | G23: =+'18'!F53 -> 0 | H23: =+'18'!G53 -> 0 | I23: =SUM(C23:H23) -> 0 | J23: =+'18'!H53 -> 0 | K23: =+J23-I23 -> 0
A24: =+Input!B28 -> Tuesday | B24: =+Input!C28 -> 46161 | C24: =+'19'!B53 -> 0 | D24: =+'19'!C53 -> 0 | E24: =+'19'!D53 -> 0 | F24: =+'19'!E53 -> 0 | G24: =+'19'!F53 -> 0 | H24: =+'19'!G53 -> 0 | I24: =SUM(C24:H24) -> 0 | J24: =+'19'!H53 -> 0 | K24: =+J24-I24 -> 0
A25: =+Input!B29 -> Wednesday | B25: =+Input!C29 -> 46162 | C25: =+'20'!B53 -> 0 | D25: =+'20'!C53 -> 0 | E25: =+'20'!D53 -> 0 | F25: =+'20'!E53 -> 0 | G25: =+'20'!F53 -> 0 | H25: =+'20'!G53 -> 0 | I25: =SUM(C25:H25) -> 0 | J25: =+'20'!H53 -> 0 | K25: =+J25-I25 -> 0
A26: =+Input!B30 -> Thursday | B26: =+Input!C30 -> 46163 | C26: =+'21'!B53 -> 0 | D26: =+'21'!C53 -> 0 | E26: =+'21'!D53 -> 0 | F26: =+'21'!E53 -> 0 | G26: =+'21'!F53 -> 0 | H26: =+'21'!G53 -> 0 | I26: =SUM(C26:H26) -> 0 | J26: =+'21'!H53 -> 0 | K26: =+J26-I26 -> 0
A27: =+Input!B31 -> Friday | B27: =+Input!C31 -> 46164 | C27: =+'22'!B53 -> 0 | D27: =+'22'!C53 -> 0 | E27: =+'22'!D53 -> 0 | F27: =+'22'!E53 -> 0 | G27: =+'22'!F53 -> 0 | H27: =+'22'!G53 -> 0 | I27: =SUM(C27:H27) -> 0 | J27: =+'22'!H53 -> 0 | K27: =+J27-I27 -> 0
A28: =+Input!B32 -> Saturday | B28: =+Input!C32 -> 46165 | C28: =+'23'!B53 -> 0 | D28: =+'23'!C53 -> 0 | E28: =+'23'!D53 -> 0 | F28: =+'23'!E53 -> 0 | G28: =+'23'!F53 -> 0 | H28: =+'23'!G53 -> 0 | I28: =SUM(C28:H28) -> 0 | J28: =+'23'!H53 -> 0 | K28: =+J28-I28 -> 0
A29: =+Input!B33 -> Sunday | B29: =+Input!C33 -> 46166 | C29: =+'24'!B53 -> 0 | D29: =+'24'!C53 -> 0 | E29: =+'24'!D53 -> 0 | F29: =+'24'!E53 -> 0 | G29: =+'24'!F53 -> 0 | H29: =+'24'!G53 -> 0 | I29: =SUM(C29:H29) -> 0 | J29: =+'24'!H53 -> 0 | K29: =+J29-I29 -> 0
A30: =+Input!B34 -> Monday | B30: =+Input!C34 -> 46167 | C30: =+'25'!B53 -> 0 | D30: =+'25'!C53 -> 0 | E30: =+'25'!D53 -> 0 | F30: =+'25'!E53 -> 0 | G30: =+'25'!F53 -> 0 | H30: =+'25'!G53 -> 0 | I30: =SUM(C30:H30) -> 0 | J30: =+'25'!H53 -> 0 | K30: =+J30-I30 -> 0
A31: =+Input!B35 -> Tuesday | B31: =+Input!C35 -> 46168 | C31: =+'26'!B53 -> 0 | D31: =+'26'!C53 -> 0 | E31: =+'26'!D53 -> 0 | F31: =+'26'!E53 -> 0 | G31: =+'26'!F53 -> 0 | H31: =+'26'!G53 -> 0 | I31: =SUM(C31:H31) -> 0 | J31: =+'26'!H53 -> 0 | K31: =+J31-I31 -> 0
A32: =+Input!B36 -> Wednesday | B32: =+Input!C36 -> 46169 | C32: =+'27'!B53 -> 0 | D32: =+'27'!C53 -> 0 | E32: =+'27'!D53 -> 0 | F32: =+'27'!E53 -> 0 | G32: =+'27'!F53 -> 0 | H32: =+'27'!G53 -> 0 | I32: =SUM(C32:H32) -> 0 | J32: =+'27'!H53 -> 0 | K32: =+J32-I32 -> 0
A33: =+Input!B37 -> Thursday | B33: =+Input!C37 -> 46170 | C33: =+'28'!B53 -> 0 | D33: =+'28'!C53 -> 0 | E33: =+'28'!D53 -> 0 | F33: =+'28'!E53 -> 0 | G33: =+'28'!F53 -> 0 | H33: =+'28'!G53 -> 0 | I33: =SUM(C33:H33) -> 0 | J33: =+'28'!H53 -> 0 | K33: =+J33-I33 -> 0
A34: =+Input!B38 -> Friday | B34: =+Input!C38 -> 46171 | C34: =+'29'!B53 -> 0 | D34: =+'29'!C53 -> 0 | E34: =+'29'!D53 -> 0 | F34: =+'29'!E53 -> 0 | G34: =+'29'!F53 -> 0 | H34: =+'29'!G53 -> 0 | I34: =SUM(C34:H34) -> 0 | J34: =+'29'!H53 -> 0 | K34: =+J34-I34 -> 0
A35: =+Input!B39 -> Saturday | B35: =+Input!C39 -> 46172 | C35: =+'30'!B53 -> 0 | D35: =+'30'!C53 -> 0 | E35: =+'30'!D53 -> 0 | F35: =+'30'!E53 -> 0 | G35: =+'30'!F53 -> 0 | H35: =+'30'!G53 -> 0 | I35: =SUM(C35:H35) -> 0 | J35: =+'30'!H53 -> 0 | K35: =+J35-I35 -> 0
A36: =+Input!B40 -> Sunday | B36: =+Input!C40 -> 46173 | C36: =+'31'!B53 -> 0 | D36: =+'31'!C53 -> 0 | E36: =+'31'!D53 -> 0 | F36: =+'31'!E53 -> 0 | G36: =+'31'!F53 -> 0 | H36: =+'31'!G53 -> 0 | I36: =SUM(C36:H36) -> 0 | J36: =+'31'!H53 -> 0 | K36: =+J36-I36 -> 0
C37: =SUM(C6:C36) -> 33206.04 | D37: =SUM(D6:D36) -> -1000 | E37: =SUM(E6:E36) -> -1000 | F37: =SUM(F6:F36) -> -1000 | G37: =SUM(G6:G36) -> -1000 | H37: =SUM(H6:H36) -> -1000 | I37: =SUM(I6:I36) -> 28206.04 | J37: =SUM(J6:J36) -> 28206.04 | K37: =+J37-I37 -> 0
K38: =SUM(K6:K36)-K37 -> 0

Sheet Petty Cash Report
A1: =+Input!B2 -> ENGEN JETPARK
A3: Petty Cash Analysis | B3: =+Input!B6 -> 46143
A5: PETTY CASH | B5: 1 | C5: =+B5+1 -> 2 | D5: =+C5+1 -> 3 | E5: =+D5+1 -> 4 | F5: =+E5+1 -> 5 | G5: =+F5+1 -> 6 | H5: =+G5+1 -> 7 | I5: =+H5+1 -> 8 | J5: =+I5+1 -> 9 | ... AF5: =+AE5+1 -> 31
A6: - Cleaning | B6: =+'1'!H83 -> 0 | C6: =+'2'!H83 -> 0 | D6: =+'3'!H83 -> 0 | E6: =+'4'!H83 -> 0 | F6: =+'5'!H83 -> 0 | G6: =+'6'!H83 -> 0 | H6: =+'7'!H83 -> 0 | I6: =+'8'!H83 -> 0 | J6: =+'9'!H83 -> 0 | K6: =+'10'!H83 -> 0 | L6: =+'11'!H83 -> 0 | M6: =+'12'!H83 -> 0 | N6: =+'13'!H83 -> 0 | O6: =+'14'!H83 -> 0 | P6: =+'15'!H83 -> 0 | Q6: =+'16'!H83 -> 0 | R6: =+'17'!H83 -> 0 | S6: =+'18'!H83 -> 0 | T6: =+'19'!H83 -> 0 | U6: =+'20'!H83 -> 0 | V6: =+'21'!H83 -> 0 | W6: =+'22'!H83 -> 0 | X6: =+'23'!H83 -> 0 | Y6: =+'24'!H83 -> 0 | Z6: =+'25'!H83 -> 0 | AA6: =+'26'!H83 -> 0 | AB6: =+'27'!H83 -> 0 | AC6: =+'28'!H83 -> 0 | AD6: =+'29'!H83 -> 0 | AE6: =+'30'!H83 -> 0 | AF6: =+'31'!H83 -> 0
A7: - Creditors: Existing | B7: =+'1'!H84 -> 0 | C7: =+'2'!H84 -> 0 | D7: =+'3'!H84 -> 0 | E7: =+'4'!H84 -> 0 | F7: =+'5'!H84 -> 0 | G7: =+'6'!H84 -> 0 | H7: =+'7'!H84 -> 0 | I7: =+'8'!H84 -> 0 | J7: =+'9'!H84 -> 0 | K7: =+'10'!H84 -> 0 | L7: =+'11'!H84 -> 0 | M7: =+'12'!H84 -> 0 | N7: =+'13'!H84 -> 0 | O7: =+'14'!H84 -> 0 | P7: =+'15'!H84 -> 0 | Q7: =+'16'!H84 -> 0 | R7: =+'17'!H84 -> 0 | S7: =+'18'!H84 -> 0 | T7: =+'19'!H84 -> 0 | U7: =+'20'!H84 -> 0 | V7: =+'21'!H84 -> 0 | W7: =+'22'!H84 -> 0 | X7: =+'23'!H84 -> 0 | Y7: =+'24'!H84 -> 0 | Z7: =+'25'!H84 -> 0 | AA7: =+'26'!H84 -> 0 | AB7: =+'27'!H84 -> 0 | AC7: =+'28'!H84 -> 0 | AD7: =+'29'!H84 -> 0 | AE7: =+'30'!H84 -> 0 | AF7: =+'31'!H84 -> 0
A8: - Creditors: New | B8: =+'1'!H85 -> 0 | C8: =+'2'!H85 -> 0 | D8: =+'3'!H85 -> 0 | E8: =+'4'!H85 -> 0 | F8: =+'5'!H85 -> 0 | G8: =+'6'!H85 -> 0 | H8: =+'7'!H85 -> 0 | I8: =+'8'!H85 -> 0 | J8: =+'9'!H85 -> 0 | K8: =+'10'!H85 -> 0 | L8: =+'11'!H85 -> 0 | M8: =+'12'!H85 -> 0 | N8: =+'13'!H85 -> 0 | O8: =+'14'!H85 -> 0 | P8: =+'15'!H85 -> 0 | Q8: =+'16'!H85 -> 0 | R8: =+'17'!H85 -> 0 | S8: =+'18'!H85 -> 0 | T8: =+'19'!H85 -> 0 | U8: =+'20'!H85 -> 0 | V8: =+'21'!H85 -> 0 | W8: =+'22'!H85 -> 0 | X8: =+'23'!H85 -> 0 | Y8: =+'24'!H85 -> 0 | Z8: =+'25'!H85 -> 0 | AA8: =+'26'!H85 -> 0 | AB8: =+'27'!H85 -> 0 | AC8: =+'28'!H85 -> 0 | AD8: =+'29'!H85 -> 0 | AE8: =+'30'!H85 -> 0 | AF8: =+'31'!H85 -> 0
A9: - Forecourt: R & M | B9: =+'1'!H86 -> 0 | C9: =+'2'!H86 -> 0 | D9: =+'3'!H86 -> 0 | E9: =+'4'!H86 -> 0 | F9: =+'5'!H86 -> 0 | G9: =+'6'!H86 -> 0 | H9: =+'7'!H86 -> 0 | I9: =+'8'!H86 -> 0 | J9: =+'9'!H86 -> 0 | K9: =+'10'!H86 -> 0 | L9: =+'11'!H86 -> 0 | M9: =+'12'!H86 -> 0 | N9: =+'13'!H86 -> 0 | O9: =+'14'!H86 -> 0 | P9: =+'15'!H86 -> 0 | Q9: =+'16'!H86 -> 0 | R9: =+'17'!H86 -> 0 | S9: =+'18'!H86 -> 0 | T9: =+'19'!H86 -> 0 | U9: =+'20'!H86 -> 0 | V9: =+'21'!H86 -> 0 | W9: =+'22'!H86 -> 0 | X9: =+'23'!H86 -> 0 | Y9: =+'24'!H86 -> 0 | Z9: =+'25'!H86 -> 0 | AA9: =+'26'!H86 -> 0 | AB9: =+'27'!H86 -> 0 | AC9: =+'28'!H86 -> 0 | AD9: =+'29'!H86 -> 0 | AE9: =+'30'!H86 -> 0 | AF9: =+'31'!H86 -> 0
A10: - Other: Non-Vatable | B10: =+'1'!H87 -> 0 | C10: =+'2'!H87 -> 0 | D10: =+'3'!H87 -> 0 | E10: =+'4'!H87 -> 0 | F10: =+'5'!H87 -> 0 | G10: =+'6'!H87 -> 0 | H10: =+'7'!H87 -> 0 | I10: =+'8'!H87 -> 0 | J10: =+'9'!H87 -> 0 | K10: =+'10'!H87 -> 0 | L10: =+'11'!H87 -> 0 | M10: =+'12'!H87 -> 0 | N10: =+'13'!H87 -> 0 | O10: =+'14'!H87 -> 0 | P10: =+'15'!H87 -> 0 | Q10: =+'16'!H87 -> 0 | R10: =+'17'!H87 -> 0 | S10: =+'18'!H87 -> 0 | T10: =+'19'!H87 -> 0 | U10: =+'20'!H87 -> 0 | V10: =+'21'!H87 -> 0 | W10: =+'22'!H87 -> 0 | X10: =+'23'!H87 -> 0 | Y10: =+'24'!H87 -> 0 | Z10: =+'25'!H87 -> 0 | AA10: =+'26'!H87 -> 0 | AB10: =+'27'!H87 -> 0 | AC10: =+'28'!H87 -> 0 | AD10: =+'29'!H87 -> 0 | AE10: =+'30'!H87 -> 0 | AF10: =+'31'!H87 -> 0
A11: - Other: Non-Vatable | B11: =+'1'!H88 -> 0 | C11: =+'2'!H88 -> 0 | D11: =+'3'!H88 -> 0 | E11: =+'4'!H88 -> 0 | F11: =+'5'!H88 -> 0 | G11: =+'6'!H88 -> 0 | H11: =+'7'!H88 -> 0 | I11: =+'8'!H88 -> 0 | J11: =+'9'!H88 -> 0 | K11: =+'10'!H88 -> 0 | L11: =+'11'!H88 -> 0 | M11: =+'12'!H88 -> 0 | N11: =+'13'!H88 -> 0 | O11: =+'14'!H88 -> 0 | P11: =+'15'!H88 -> 0 | Q11: =+'16'!H88 -> 0 | R11: =+'17'!H88 -> 0 | S11: =+'18'!H88 -> 0 | T11: =+'19'!H88 -> 0 | U11: =+'20'!H88 -> 0 | V11: =+'21'!H88 -> 0 | W11: =+'22'!H88 -> 0 | X11: =+'23'!H88 -> 0 | Y11: =+'24'!H88 -> 0 | Z11: =+'25'!H88 -> 0 | AA11: =+'26'!H88 -> 0 | AB11: =+'27'!H88 -> 0 | AC11: =+'28'!H88 -> 0 | AD11: =+'29'!H88 -> 0 | AE11: =+'30'!H88 -> 0 | AF11: =+'31'!H88 -> 0
A12: - Other: Non-Vatable | B12: =+'1'!H89 -> 0 | C12: =+'2'!H89 -> 0 | D12: =+'3'!H89 -> 0 | E12: =+'4'!H89 -> 0 | F12: =+'5'!H89 -> 0 | G12: =+'6'!H89 -> 0 | H12: =+'7'!H89 -> 0 | I12: =+'8'!H89 -> 0 | J12: =+'9'!H89 -> 0 | K12: =+'10'!H89 -> 0 | L12: =+'11'!H89 -> 0 | M12: =+'12'!H89 -> 0 | N12: =+'13'!H89 -> 0 | O12: =+'14'!H89 -> 0 | P12: =+'15'!H89 -> 0 | Q12: =+'16'!H89 -> 0 | R12: =+'17'!H89 -> 0 | S12: =+'18'!H89 -> 0 | T12: =+'19'!H89 -> 0 | U12: =+'20'!H89 -> 0 | V12: =+'21'!H89 -> 0 | W12: =+'22'!H89 -> 0 | X12: =+'23'!H89 -> 0 | Y12: =+'24'!H89 -> 0 | Z12: =+'25'!H89 -> 0 | AA12: =+'26'!H89 -> 0 | AB12: =+'27'!H89 -> 0 | AC12: =+'28'!H89 -> 0 | AD12: =+'29'!H89 -> 0 | AE12: =+'30'!H89 -> 0 | AF12: =+'31'!H89 -> 0
A13: - Other: Vatable | B13: =+'1'!H90 -> 0 | C13: =+'2'!H90 -> 0 | D13: =+'3'!H90 -> 0 | E13: =+'4'!H90 -> 0 | F13: =+'5'!H90 -> 0 | G13: =+'6'!H90 -> 0 | H13: =+'7'!H90 -> 0 | I13: =+'8'!H90 -> 0 | J13: =+'9'!H90 -> 0 | K13: =+'10'!H90 -> 0 | L13: =+'11'!H90 -> 0 | M13: =+'12'!H90 -> 0 | N13: =+'13'!H90 -> 0 | O13: =+'14'!H90 -> 0 | P13: =+'15'!H90 -> 0 | Q13: =+'16'!H90 -> 0 | R13: =+'17'!H90 -> 0 | S13: =+'18'!H90 -> 0 | T13: =+'19'!H90 -> 0 | U13: =+'20'!H90 -> 0 | V13: =+'21'!H90 -> 0 | W13: =+'22'!H90 -> 0 | X13: =+'23'!H90 -> 0 | Y13: =+'24'!H90 -> 0 | Z13: =+'25'!H90 -> 0 | AA13: =+'26'!H90 -> 0 | AB13: =+'27'!H90 -> 0 | AC13: =+'28'!H90 -> 0 | AD13: =+'29'!H90 -> 0 | AE13: =+'30'!H90 -> 0 | AF13: =+'31'!H90 -> 0
A14: - Other: Vatable | B14: =+'1'!H91 -> 0 | C14: =+'2'!H91 -> 0 | D14: =+'3'!H91 -> 0 | E14: =+'4'!H91 -> 0 | F14: =+'5'!H91 -> 0 | G14: =+'6'!H91 -> 0 | H14: =+'7'!H91 -> 0 | I14: =+'8'!H91 -> 0 | J14: =+'9'!H91 -> 0 | K14: =+'10'!H91 -> 0 | L14: =+'11'!H91 -> 0 | M14: =+'12'!H91 -> 0 | N14: =+'13'!H91 -> 0 | O14: =+'14'!H91 -> 0 | P14: =+'15'!H91 -> 0 | Q14: =+'16'!H91 -> 0 | R14: =+'17'!H91 -> 0 | S14: =+'18'!H91 -> 0 | T14: =+'19'!H91 -> 0 | U14: =+'20'!H91 -> 0 | V14: =+'21'!H91 -> 0 | W14: =+'22'!H91 -> 0 | X14: =+'23'!H91 -> 0 | Y14: =+'24'!H91 -> 0 | Z14: =+'25'!H91 -> 0 | AA14: =+'26'!H91 -> 0 | AB14: =+'27'!H91 -> 0 | AC14: =+'28'!H91 -> 0 | AD14: =+'29'!H91 -> 0 | AE14: =+'30'!H91 -> 0 | AF14: =+'31'!H91 -> 0
A15: - Other: Vatable | B15: =+'1'!H92 -> 0 | C15: =+'2'!H92 -> 0 | D15: =+'3'!H92 -> 0 | E15: =+'4'!H92 -> 0 | F15: =+'5'!H92 -> 0 | G15: =+'6'!H92 -> 0 | H15: =+'7'!H92 -> 0 | I15: =+'8'!H92 -> 0 | J15: =+'9'!H92 -> 0 | K15: =+'10'!H92 -> 0 | L15: =+'11'!H92 -> 0 | M15: =+'12'!H92 -> 0 | N15: =+'13'!H92 -> 0 | O15: =+'14'!H92 -> 0 | P15: =+'15'!H92 -> 0 | Q15: =+'16'!H92 -> 0 | R15: =+'17'!H92 -> 0 | S15: =+'18'!H92 -> 0 | T15: =+'19'!H92 -> 0 | U15: =+'20'!H92 -> 0 | V15: =+'21'!H92 -> 0 | W15: =+'22'!H92 -> 0 | X15: =+'23'!H92 -> 0 | Y15: =+'24'!H92 -> 0 | Z15: =+'25'!H92 -> 0 | AA15: =+'26'!H92 -> 0 | AB15: =+'27'!H92 -> 0 | AC15: =+'28'!H92 -> 0 | AD15: =+'29'!H92 -> 0 | AE15: =+'30'!H92 -> 0 | AF15: =+'31'!H92 -> 0
A16: - Printing & Stationery | B16: =+'1'!H93 -> 0 | C16: =+'2'!H93 -> 0 | D16: =+'3'!H93 -> 0 | E16: =+'4'!H93 -> 0 | F16: =+'5'!H93 -> 0 | G16: =+'6'!H93 -> 0 | H16: =+'7'!H93 -> 0 | I16: =+'8'!H93 -> 0 | J16: =+'9'!H93 -> 0 | K16: =+'10'!H93 -> 0 | L16: =+'11'!H93 -> 0 | M16: =+'12'!H93 -> 0 | N16: =+'13'!H93 -> 0 | O16: =+'14'!H93 -> 0 | P16: =+'15'!H93 -> 0 | Q16: =+'16'!H93 -> 0 | R16: =+'17'!H93 -> 0 | S16: =+'18'!H93 -> 0 | T16: =+'19'!H93 -> 0 | U16: =+'20'!H93 -> 0 | V16: =+'21'!H93 -> 0 | W16: =+'22'!H93 -> 0 | X16: =+'23'!H93 -> 0 | Y16: =+'24'!H93 -> 0 | Z16: =+'25'!H93 -> 0 | AA16: =+'26'!H93 -> 0 | AB16: =+'27'!H93 -> 0 | AC16: =+'28'!H93 -> 0 | AD16: =+'29'!H93 -> 0 | AE16: =+'30'!H93 -> 0 | AF16: =+'31'!H93 -> 0
A17: - Retail: R & M | B17: =+'1'!H94 -> 0 | C17: =+'2'!H94 -> 0 | D17: =+'3'!H94 -> 0 | E17: =+'4'!H94 -> 0 | F17: =+'5'!H94 -> 0 | G17: =+'6'!H94 -> 0 | H17: =+'7'!H94 -> 0 | I17: =+'8'!H94 -> 0 | J17: =+'9'!H94 -> 0 | K17: =+'10'!H94 -> 0 | L17: =+'11'!H94 -> 0 | M17: =+'12'!H94 -> 0 | N17: =+'13'!H94 -> 0 | O17: =+'14'!H94 -> 0 | P17: =+'15'!H94 -> 0 | Q17: =+'16'!H94 -> 0 | R17: =+'17'!H94 -> 0 | S17: =+'18'!H94 -> 0 | T17: =+'19'!H94 -> 0 | U17: =+'20'!H94 -> 0 | V17: =+'21'!H94 -> 0 | W17: =+'22'!H94 -> 0 | X17: =+'23'!H94 -> 0 | Y17: =+'24'!H94 -> 0 | Z17: =+'25'!H94 -> 0 | AA17: =+'26'!H94 -> 0 | AB17: =+'27'!H94 -> 0 | AC17: =+'28'!H94 -> 0 | AD17: =+'29'!H94 -> 0 | AE17: =+'30'!H94 -> 0 | AF17: =+'31'!H94 -> 0
... A21: - Wages | B21: =+'1'!H98 -> 0 | C21: =+'2'!H98 -> 0 | D21: =+'3'!H98 -> 0 | E21: =+'4'!H98 -> 0 | F21: =+'5'!H98 -> 0 | G21: =+'6'!H98 -> 0 | H21: =+'7'!H98 -> 0 | I21: =+'8'!H98 -> 0 | J21: =+'9'!H98 -> 0 | K21: =+'10'!H98 -> 0 | L21: =+'11'!H98 -> 0 | M21: =+'12'!H98 -> 0 | N21: =+'13'!H98 -> 0 | O21: =+'14'!H98 -> 0 | P21: =+'15'!H98 -> 0 | Q21: =+'16'!H98 -> 0 | R21: =+'17'!H98 -> 0 | S21: =+'18'!H98 -> 0 | T21: =+'19'!H98 -> 0 | U21: =+'20'!H98 -> 0 | V21: =+'21'!H98 -> 0 | W21: =+'22'!H98 -> 0 | X21: =+'23'!H98 -> 0 | Y21: =+'24'!H98 -> 0 | Z21: =+'25'!H98 -> 0 | AA21: =+'26'!H98 -> 0 | AB21: =+'27'!H98 -> 0 | AC21: =+'28'!H98 -> 0 | AD21: =+'29'!H98 -> 0 | AE21: =+'30'!H98 -> 0 | AF21: =+'31'!H98 -> 0
A22: - TOTAL | B22: =SUM(B6:B21) -> 0 | C22: =SUM(C6:C21) -> 0 | D22: =SUM(D6:D21) -> 0 | E22: =SUM(E6:E21) -> 0 | F22: =SUM(F6:F21) -> 0 | G22: =SUM(G6:G21) -> 0 | H22: =SUM(H6:H21) -> 0 | I22: =SUM(I6:I21) -> 0 | ... AF22: =SUM(AF6:AF21) -> 0
A23: - TOTAL B/FWD | B23: =+'1'!H82 -> 0 | C23: =+'2'!H82 -> 0 | D23: =+'3'!H82 -> 0 | E23: =+'4'!H82 -> 0 | F23: =+'5'!H82 -> 0 | G23: =+'6'!H82 -> 0 | H23: =+'7'!H82 -> 0 | I23: =+'8'!H82 -> 0 | J23: =+'9'!H82 -> 0 | K23: =+'10'!H82 -> 0 | L23: =+'11'!H82 -> 0 | M23: =+'12'!H82 -> 0 | N23: =+'13'!H82 -> 0 | O23: =+'14'!H82 -> 0 | P23: =+'15'!H82 -> 0 | Q23: =+'16'!H82 -> 0 | R23: =+'17'!H82 -> 0 | S23: =+'18'!H82 -> 0 | T23: =+'19'!H82 -> 0 | U23: =+'20'!H82 -> 0 | V23: =+'21'!H82 -> 0 | W23: =+'22'!H82 -> 0 | X23: =+'23'!H82 -> 0 | Y23: =+'24'!H82 -> 0 | Z23: =+'25'!H82 -> 0 | AA23: =+'26'!H82 -> 0 | AB23: =+'27'!H82 -> 0 | AC23: =+'28'!H82 -> 0 | AD23: =+'29'!H82 -> 0 | AE23: =+'30'!H82 -> 0 | AF23: =+'31'!H82 -> 0
A24: - VARIANCE | B24: =+B22-B23 -> 0 | C24: =+C22-C23 -> 0 | D24: =+D22-D23 -> 0 | E24: =+E22-E23 -> 0 | F24: =+F22-F23 -> 0 | G24: =+G22-G23 -> 0 | H24: =+H22-H23 -> 0 | I24: =+I22-I23 -> 0 | ... AF24: =+AF22-AF23 -> 0
A26: CREDITORS: EXISTING
A27: =+Input!A55 -> - Aksia Sales | B27: =+'1'!H102 -> 0 | C27: =+'2'!H102 -> 0 | D27: =+'3'!H102 -> 0 | E27: =+'4'!H102 -> 0 | F27: =+'5'!H102 -> 0 | G27: =+'6'!H102 -> 0 | H27: =+'7'!H102 -> 0 | I27: =+'8'!H102 -> 0 | J27: =+'9'!H102 -> 0 | K27: =+'10'!H102 -> 0 | L27: =+'11'!H102 -> 0 | M27: =+'12'!H102 -> 0 | N27: =+'13'!H102 -> 0 | O27: =+'14'!H102 -> 0 | P27: =+'15'!H102 -> 0 | Q27: =+'16'!H102 -> 0 | R27: =+'17'!H102 -> 0 | S27: =+'18'!H102 -> 0 | T27: =+'19'!H102 -> 0 | U27: =+'20'!H102 -> 0 | V27: =+'21'!H102 -> 0 | W27: =+'22'!H102 -> 0 | X27: =+'23'!H102 -> 0 | Y27: =+'24'!H102 -> 0 | Z27: =+'25'!H102 -> 0 | AA27: =+'26'!H102 -> 0 | AB27: =+'27'!H102 -> 0 | AC27: =+'28'!H102 -> 0 | AD27: =+'29'!H102 -> 0 | AE27: =+'30'!H102 -> 0 | AF27: =+'31'!H102 -> 0
A28: =+Input!A56 -> - Albany | B28: =+'1'!H103 -> 0 | C28: =+'2'!H103 -> 0 | D28: =+'3'!H103 -> 0 | E28: =+'4'!H103 -> 0 | F28: =+'5'!H103 -> 0 | G28: =+'6'!H103 -> 0 | H28: =+'7'!H103 -> 0 | I28: =+'8'!H103 -> 0 | J28: =+'9'!H103 -> 0 | K28: =+'10'!H103 -> 0 | L28: =+'11'!H103 -> 0 | M28: =+'12'!H103 -> 0 | N28: =+'13'!H103 -> 0 | O28: =+'14'!H103 -> 0 | P28: =+'15'!H103 -> 0 | Q28: =+'16'!H103 -> 0 | R28: =+'17'!H103 -> 0 | S28: =+'18'!H103 -> 0 | T28: =+'19'!H103 -> 0 | U28: =+'20'!H103 -> 0 | V28: =+'21'!H103 -> 0 | W28: =+'22'!H103 -> 0 | X28: =+'23'!H103 -> 0 | Y28: =+'24'!H103 -> 0 | Z28: =+'25'!H103 -> 0 | AA28: =+'26'!H103 -> 0 | AB28: =+'27'!H103 -> 0 | AC28: =+'28'!H103 -> 0 | AD28: =+'29'!H103 -> 0 | AE28: =+'30'!H103 -> 0 | AF28: =+'31'!H103 -> 0
A29: =+Input!A57 -> - Atlantic Ice | B29: =+'1'!H104 -> 0 | C29: =+'2'!H104 -> 0 | D29: =+'3'!H104 -> 0 | E29: =+'4'!H104 -> 0 | F29: =+'5'!H104 -> 0 | G29: =+'6'!H104 -> 0 | H29: =+'7'!H104 -> 0 | I29: =+'8'!H104 -> 0 | J29: =+'9'!H104 -> 0 | K29: =+'10'!H104 -> 0 | L29: =+'11'!H104 -> 0 | M29: =+'12'!H104 -> 0 | N29: =+'13'!H104 -> 0 | O29: =+'14'!H104 -> 0 | P29: =+'15'!H104 -> 0 | Q29: =+'16'!H104 -> 0 | R29: =+'17'!H104 -> 0 | S29: =+'18'!H104 -> 0 | T29: =+'19'!H104 -> 0 | U29: =+'20'!H104 -> 0 | V29: =+'21'!H104 -> 0 | W29: =+'22'!H104 -> 0 | X29: =+'23'!H104 -> 0 | Y29: =+'24'!H104 -> 0 | Z29: =+'25'!H104 -> 0 | AA29: =+'26'!H104 -> 0 | AB29: =+'27'!H104 -> 0 | AC29: =+'28'!H104 -> 0 | AD29: =+'29'!H104 -> 0 | AE29: =+'30'!H104 -> 0 | AF29: =+'31'!H104 -> 0
A30: =+Input!A58 -> - Bake It Easy | B30: =+'1'!H105 -> 0 | C30: =+'2'!H105 -> 0 | D30: =+'3'!H105 -> 0 | E30: =+'4'!H105 -> 0 | F30: =+'5'!H105 -> 0 | G30: =+'6'!H105 -> 0 | H30: =+'7'!H105 -> 0 | I30: =+'8'!H105 -> 0 | J30: =+'9'!H105 -> 0 | K30: =+'10'!H105 -> 0 | L30: =+'11'!H105 -> 0 | M30: =+'12'!H105 -> 0 | N30: =+'13'!H105 -> 0 | O30: =+'14'!H105 -> 0 | P30: =+'15'!H105 -> 0 | Q30: =+'16'!H105 -> 0 | R30: =+'17'!H105 -> 0 | S30: =+'18'!H105 -> 0 | T30: =+'19'!H105 -> 0 | U30: =+'20'!H105 -> 0 | V30: =+'21'!H105 -> 0 | W30: =+'22'!H105 -> 0 | X30: =+'23'!H105 -> 0 | Y30: =+'24'!H105 -> 0 | Z30: =+'25'!H105 -> 0 | AA30: =+'26'!H105 -> 0 | AB30: =+'27'!H105 -> 0 | AC30: =+'28'!H105 -> 0 | AD30: =+'29'!H105 -> 0 | AE30: =+'30'!H105 -> 0 | AF30: =+'31'!H105 -> 0
A31: =+Input!A59 -> - Bamco Tabacco | B31: =+'1'!H106 -> 0 | C31: =+'2'!H106 -> 0 | D31: =+'3'!H106 -> 0 | E31: =+'4'!H106 -> 0 | F31: =+'5'!H106 -> 0 | G31: =+'6'!H106 -> 0 | H31: =+'7'!H106 -> 0 | I31: =+'8'!H106 -> 0 | J31: =+'9'!H106 -> 0 | K31: =+'10'!H106 -> 0 | L31: =+'11'!H106 -> 0 | M31: =+'12'!H106 -> 0 | N31: =+'13'!H106 -> 0 | O31: =+'14'!H106 -> 0 | P31: =+'15'!H106 -> 0 | Q31: =+'16'!H106 -> 0 | R31: =+'17'!H106 -> 0 | S31: =+'18'!H106 -> 0 | T31: =+'19'!H106 -> 0 | U31: =+'20'!H106 -> 0 | V31: =+'21'!H106 -> 0 | W31: =+'22'!H106 -> 0 | X31: =+'23'!H106 -> 0 | Y31: =+'24'!H106 -> 0 | Z31: =+'25'!H106 -> 0 | AA31: =+'26'!H106 -> 0 | AB31: =+'27'!H106 -> 0 | AC31: =+'28'!H106 -> 0 | AD31: =+'29'!H106 -> 0 | AE31: =+'30'!H106 -> 0 | AF31: =+'31'!H106 -> 0
A32: =+Input!A60 -> - Blue Ribbon | B32: =+'1'!H107 -> 0 | C32: =+'2'!H107 -> 0 | D32: =+'3'!H107 -> 0 | E32: =+'4'!H107 -> 0 | F32: =+'5'!H107 -> 0 | G32: =+'6'!H107 -> 0 | H32: =+'7'!H107 -> 0 | I32: =+'8'!H107 -> 0 | J32: =+'9'!H107 -> 0 | K32: =+'10'!H107 -> 0 | L32: =+'11'!H107 -> 0 | M32: =+'12'!H107 -> 0 | N32: =+'13'!H107 -> 0 | O32: =+'14'!H107 -> 0 | P32: =+'15'!H107 -> 0 | Q32: =+'16'!H107 -> 0 | R32: =+'17'!H107 -> 0 | S32: =+'18'!H107 -> 0 | T32: =+'19'!H107 -> 0 | U32: =+'20'!H107 -> 0 | V32: =+'21'!H107 -> 0 | W32: =+'22'!H107 -> 0 | X32: =+'23'!H107 -> 0 | Y32: =+'24'!H107 -> 0 | Z32: =+'25'!H107 -> 0 | AA32: =+'26'!H107 -> 0 | AB32: =+'27'!H107 -> 0 | AC32: =+'28'!H107 -> 0 | AD32: =+'29'!H107 -> 0 | AE32: =+'30'!H107 -> 0 | AF32: =+'31'!H107 -> 0
A33: =+Input!A61 -> - Catercorp | B33: =+'1'!H108 -> 0 | C33: =+'2'!H108 -> 0 | D33: =+'3'!H108 -> 0 | E33: =+'4'!H108 -> 0 | F33: =+'5'!H108 -> 0 | G33: =+'6'!H108 -> 0 | H33: =+'7'!H108 -> 0 | I33: =+'8'!H108 -> 0 | J33: =+'9'!H108 -> 0 | K33: =+'10'!H108 -> 0 | L33: =+'11'!H108 -> 0 | M33: =+'12'!H108 -> 0 | N33: =+'13'!H108 -> 0 | O33: =+'14'!H108 -> 0 | P33: =+'15'!H108 -> 0 | Q33: =+'16'!H108 -> 0 | R33: =+'17'!H108 -> 0 | S33: =+'18'!H108 -> 0 | T33: =+'19'!H108 -> 0 | U33: =+'20'!H108 -> 0 | V33: =+'21'!H108 -> 0 | W33: =+'22'!H108 -> 0 | X33: =+'23'!H108 -> 0 | Y33: =+'24'!H108 -> 0 | Z33: =+'25'!H108 -> 0 | AA33: =+'26'!H108 -> 0 | AB33: =+'27'!H108 -> 0 | AC33: =+'28'!H108 -> 0 | AD33: =+'29'!H108 -> 0 | AE33: =+'30'!H108 -> 0 | AF33: =+'31'!H108 -> 0
A34: =+Input!A62 -> - Checkers | B34: =+'1'!H109 -> 0 | C34: =+'2'!H109 -> 0 | D34: =+'3'!H109 -> 0 | E34: =+'4'!H109 -> 0 | F34: =+'5'!H109 -> 0 | G34: =+'6'!H109 -> 0 | H34: =+'7'!H109 -> 0 | I34: =+'8'!H109 -> 0 | J34: =+'9'!H109 -> 0 | K34: =+'10'!H109 -> 0 | L34: =+'11'!H109 -> 0 | M34: =+'12'!H109 -> 0 | N34: =+'13'!H109 -> 0 | O34: =+'14'!H109 -> 0 | P34: =+'15'!H109 -> 0 | Q34: =+'16'!H109 -> 0 | R34: =+'17'!H109 -> 0 | S34: =+'18'!H109 -> 0 | T34: =+'19'!H109 -> 0 | U34: =+'20'!H109 -> 0 | V34: =+'21'!H109 -> 0 | W34: =+'22'!H109 -> 0 | X34: =+'23'!H109 -> 0 | Y34: =+'24'!H109 -> 0 | Z34: =+'25'!H109 -> 0 | AA34: =+'26'!H109 -> 0 | AB34: =+'27'!H109 -> 0 | AC34: =+'28'!H109 -> 0 | AD34: =+'29'!H109 -> 0 | AE34: =+'30'!H109 -> 0 | AF34: =+'31'!H109 -> 0
A35: =+Input!A63 -> - Clover | B35: =+'1'!H110 -> 0 | C35: =+'2'!H110 -> 0 | D35: =+'3'!H110 -> 0 | E35: =+'4'!H110 -> 0 | F35: =+'5'!H110 -> 0 | G35: =+'6'!H110 -> 0 | H35: =+'7'!H110 -> 0 | I35: =+'8'!H110 -> 0 | J35: =+'9'!H110 -> 0 | K35: =+'10'!H110 -> 0 | L35: =+'11'!H110 -> 0 | M35: =+'12'!H110 -> 0 | N35: =+'13'!H110 -> 0 | O35: =+'14'!H110 -> 0 | P35: =+'15'!H110 -> 0 | Q35: =+'16'!H110 -> 0 | R35: =+'17'!H110 -> 0 | S35: =+'18'!H110 -> 0 | T35: =+'19'!H110 -> 0 | U35: =+'20'!H110 -> 0 | V35: =+'21'!H110 -> 0 | W35: =+'22'!H110 -> 0 | X35: =+'23'!H110 -> 0 | Y35: =+'24'!H110 -> 0 | Z35: =+'25'!H110 -> 0 | AA35: =+'26'!H110 -> 0 | AB35: =+'27'!H110 -> 0 | AC35: =+'28'!H110 -> 0 | AD35: =+'29'!H110 -> 0 | AE35: =+'30'!H110 -> 0 | AF35: =+'31'!H110 -> 0
A36: =+Input!A64 -> - Cool Runnings | B36: =+'1'!H111 -> 0 | C36: =+'2'!H111 -> 0 | D36: =+'3'!H111 -> 0 | E36: =+'4'!H111 -> 0 | F36: =+'5'!H111 -> 0 | G36: =+'6'!H111 -> 0 | H36: =+'7'!H111 -> 0 | I36: =+'8'!H111 -> 0 | J36: =+'9'!H111 -> 0 | K36: =+'10'!H111 -> 0 | L36: =+'11'!H111 -> 0 | M36: =+'12'!H111 -> 0 | N36: =+'13'!H111 -> 0 | O36: =+'14'!H111 -> 0 | P36: =+'15'!H111 -> 0 | Q36: =+'16'!H111 -> 0 | R36: =+'17'!H111 -> 0 | S36: =+'18'!H111 -> 0 | T36: =+'19'!H111 -> 0 | U36: =+'20'!H111 -> 0 | V36: =+'21'!H111 -> 0 | W36: =+'22'!H111 -> 0 | X36: =+'23'!H111 -> 0 | Y36: =+'24'!H111 -> 0 | Z36: =+'25'!H111 -> 0 | AA36: =+'26'!H111 -> 0 | AB36: =+'27'!H111 -> 0 | AC36: =+'28'!H111 -> 0 | AD36: =+'29'!H111 -> 0 | AE36: =+'30'!H111 -> 0 | AF36: =+'31'!H111 -> 0
A37: =+Input!A65 -> - Deep Frozen | B37: =+'1'!H112 -> 0 | C37: =+'2'!H112 -> 0 | D37: =+'3'!H112 -> 0 | E37: =+'4'!H112 -> 0 | F37: =+'5'!H112 -> 0 | G37: =+'6'!H112 -> 0 | H37: =+'7'!H112 -> 0 | I37: =+'8'!H112 -> 0 | J37: =+'9'!H112 -> 0 | K37: =+'10'!H112 -> 0 | L37: =+'11'!H112 -> 0 | M37: =+'12'!H112 -> 0 | N37: =+'13'!H112 -> 0 | O37: =+'14'!H112 -> 0 | P37: =+'15'!H112 -> 0 | Q37: =+'16'!H112 -> 0 | R37: =+'17'!H112 -> 0 | S37: =+'18'!H112 -> 0 | T37: =+'19'!H112 -> 0 | U37: =+'20'!H112 -> 0 | V37: =+'21'!H112 -> 0 | W37: =+'22'!H112 -> 0 | X37: =+'23'!H112 -> 0 | Y37: =+'24'!H112 -> 0 | Z37: =+'25'!H112 -> 0 | AA37: =+'26'!H112 -> 0 | AB37: =+'27'!H112 -> 0 | AC37: =+'28'!H112 -> 0 | AD37: =+'29'!H112 -> 0 | AE37: =+'30'!H112 -> 0 | AF37: =+'31'!H112 -> 0
